Workbook

Sheet Main Statistics
C8: Main Statistics | D8: Alt 1 | E8: Alt 2 | F8: Alt 3 | G8: Alt 4 | H8: Alt 5
C9: Mean NPV | D9: ='NPV - Allt.1'!I20 -> 3.0930249e+09 | E9: ='NPV - Allt.2'!K21 -> 3.1191679e+09 | F9: ='NPV - Allt.3'!P13 -> 2.957658e+09 | G9: ='NPV - Allt.4'!O11 -> 2.9608142e+09 | H9: ='NPV - Allt5.'!M13 -> 3.1435108e+09
C10: 95 % CL range | D10: ='NPV - Allt.1'!W26 -> 22467362 | E10: ='NPV - Allt.2'!X28 -> 27692377 | F10: ='NPV - Allt.3'!AD19 -> 16153996 | G10: ='NPV - Allt.4'!R17 -> 20032439 | H10: ='NPV - Allt5.'!AA19 -> 18540898
C11: Standard Deviation | D11: ='NPV - Allt.1'!I24 -> 1.8124832e+08 | E11: ='NPV - Allt.2'!K25 -> 2.2339947e+08 | F11: ='NPV - Allt.3'!P17 -> 1.3031724e+08 | G11: ='NPV - Allt.4'!O15 -> 1.6160535e+08 | H11: ='NPV - Allt5.'!M17 -> 1.4957282e+08
C12: Min | D12: ='NPV - Allt.1'!I29 -> 2.5214565e+09 | E12: ='NPV - Allt.2'!K30 -> 2.2263695e+09 | F12: ='NPV - Allt.3'!P22 -> 2.5593149e+09 | G12: ='NPV - Allt.4'!O20 -> 2.4204575e+09 | H12: ='NPV - Allt5.'!M22 -> 2.6249396e+09
C13: Max | D13: ='NPV - Allt.1'!I30 -> 3.6743832e+09 | E13: ='NPV - Allt.2'!K31 -> 3.7900394e+09 | F13: ='NPV - Allt.3'!P23 -> 3.3726707e+09 | G13: ='NPV - Allt.4'!O21 -> 3.4670212e+09 | H13: ='NPV - Allt5.'!M23 -> 3.6352797e+09
C14: Probability of NPV < 1,7 Billion | D14: ='NPV - Allt.1'!G20 -> 0 | E14: ='NPV - Allt.2'!H21 -> 0 | F14: ='NPV - Allt.3'!M12 -> 0 | G14: ='NPV - Allt.4'!L11 -> 0 | H14: ='NPV - Allt5.'!K9 -> 0
C15: Count | D15: 1000 | E15: 1000 | F15: 1000 | G15: 1000 | H15: 1000

Sheet Varity A - Carménère
AF1: Exponential distribution | AL1: Adjusting yield to deases risk
C2: All calculations related to Varity A - Carménère | M2: Annual Demand | T2: Farming tecniques: | W2: Material costs per hectar | AC2: Disese occurance | AF2: Traditonal | AI2: Modern | AL2: Traditional | AN2: Modern
M3: Mean | N3: 1.015 | T3: Traditional farming | U3: Modern farming | W3: Traditinal farming | Z3: Modern farming | AC3: 5 % probability of occuring each year | AF3: Lambda | AG3: 5 | AI3: 10 | AT3: Annual revenue | AV3: Costs | AX3: Disease events | AZ3: Yield | BB3: Profit per year
M4: STD | N4: 0.05 | S4: Annual fixed cost per hectar | T4: 3500000 | U4: 5500000 | W4: Mean | X4: 1300000 | Z4: Mean | AA4: 2000000 | AC4: 0 if it dosent occure, 1 if it does | AF4: Average | AG4: 0.1 | AI4: 0.2
S5: Effect on the annual yield in percentage | T5: 0.95 | U5: 1.1 | W5: STD | X5: 160000 | Z5: STD | AA5: 130000
S6: Total hectar per year | T6: 20 | U6: 20 | AC6: Year 1 | AD6: =IF(RAND() < 0.05, 1, 0) -> 0 | AF6: Year 1 | AG6: =IF(AD6=1, -LN(RAND()) / 5, 0) -> 0 | AI6: =IF(AD6=1, -LN(RAND()) / 10, 0) -> 0 | AK6: Year 1 | AL6: =T10 * (1 - AG6) -> 13.542828 | AN6: =U10 * (1 - AI6) -> 15.681169
C7: Price per ton - Normal distribution | F7: Annual yield (avkastning) - Triangular distribution | L7: Year 1 | M7: 200 | W7: Scaled mean | X7: 14.0725 | Z7: Scaled mean | AA7: 14.5066 | AC7: Year 2 | AD7: =IF(RAND() < 0.05, 1, 0) -> 0 | AF7: Year 2 | AG7: =IF(AD7=1, -LN(RAND()) / 5, 0) -> 0 | AI7: =IF(AD7=1, -LN(RAND()) / 10, 0) -> 0 | AK7: Year 2 | AL7: =T11 * (1 - AG7) -> 13.038875 | AN7: =U11 * (1 - AI7) -> 15.097645
C8: Mean | D8: 1500000 | F8: Min | G8: 8 | L8: Year 2 | M8: =M7 * _xlfn.NORM.INV(RAND(),N3,N4) -> 202.24749 | S8: Fixed cost per year (20 hectar) | T8: =T4*T6 -> 70000000 | U8: =U4*U6 -> 110000000 | W8: Scaled STD | X8: 0.12258 | Z8: Scaled STD | AA8: 0.0649 | AC8: Year 3 | AD8: =IF(RAND() < 0.05, 1, 0) -> 0 | AF8: Year 3 | AG8: =IF(AD8=1, -LN(RAND()) / 5, 0) -> 0 | AI8: =IF(AD8=1, -LN(RAND()) / 10, 0) -> 0 | AK8: Year 3 | AL8: =T12 * (1 - AG8) -> 14.876227 | AN8: =U12 * (1 - AI8) -> 17.225105
C9: STD | D9: 110000 | F9: Likely | G9: 13 | L9: Year 3 | M9: =M8 * _xlfn.NORM.INV(RAND(), N3,N4) -> 195.88246 | T9: Adjusted yield traditional | U9: Adjusted yield modern | AC9: Year 4 | AD9: =IF(RAND() < 0.05, 1, 0) -> 0 | AF9: Year 4 | AG9: =IF(AD9=1, -LN(RAND()) / 5, 0) -> 0 | AI9: =IF(AD9=1, -LN(RAND()) / 10, 0) -> 0 | AK9: Year 4 | AL9: =T13 * (1 - AG9) -> 11.703023 | AN9: =U13 * (1 - AI9) -> 13.550869 | AT9: Traditional | AU9: Modern | AV9: Traditonal | AW9: Modern | AX9: Traditional | AY9: Modern | AZ9: Traditional | BA9: Modern | BB9: Traditonal | BC9: Modern
F10: Max | G10: 18 | L10: Year 4 | M10: =M9 * _xlfn.NORM.INV(RAND(),N3,N4) -> 193.65322 | S10: Year 1 | T10: =G12*$T$5 -> 13.542828 | U10: =G12*$U$5 -> 15.681169 | AC10: Year 5 | AD10: =IF(RAND() < 0.05, 1, 0) -> 0 | AF10: Year 5 | AG10: =IF(AD10=1, -LN(RAND()) / 5, 0) -> 0 | AI10: =IF(AD10=1, -LN(RAND()) / 10, 0) -> 0 | AK10: Year 5 | AL10: =T14 * (1 - AG10) -> 14.693422 | AN10: =U14 * (1 - AI10) -> 17.013436 | AS10: Year 1 | AT10: =MIN(AL6,M7) * C11 * 20 -> 4.136699e+08 | AU10: =MIN(AN6,M7) * C11 * 20 -> 4.789862e+08 | AV10: =$T$8 + X14 * 20 -> 95030228 | AW10: =$U$8+AA14 * 20 -> 1.4770631e+08 | AX10: =SUM(AD6:AD25) -> 1 | AY10: =SUM(AD6:AD25) -> 1 | AZ10: =AL6 -> 13.542828 | BA10: =AN6 -> 15.681169 | BB10: =AT10-AV10 -> 3.1863967e+08 | BC10: =AU10-AW10 -> 3.312799e+08
B11: Year 1 | C11: =_xlfn.NORM.INV(RAND(),1500000,110000) -> 1527265.6 | L11: Year 5 | M11: =M10 * _xlfn.NORM.INV(RAND(),N3,N4) -> 214.22804 | S11: Year 2 | T11: =G13*$T$5 -> 13.038875 | U11: =G13*$U$5 -> 15.097645 | AC11: Year 6 | AD11: =IF(RAND() < 0.05, 1, 0) -> 0 | AF11: Year 6 | AG11: =IF(AD11=1, -LN(RAND()) / 5, 0) -> 0 | AI11: =IF(AD11=1, -LN(RAND()) / 10, 0) -> 0 | AK11: Year 6 | AL11: =T15 * (1 - AG11) -> 10.676203 | AN11: =U15 * (1 - AI11) -> 12.361919 | AS11: Year 2 | AT11: =MIN(AL7,M8) * C12 * 20 -> 4.174718e+08 | AU11: =MIN(AN7,M8) * C12 * 20 -> 4.833884e+08 | AV11: =$T$8 + X15 * 20 -> 1.0048232e+08 | AW11: =$U$8+AA15 * 20 -> 1.4954647e+08 | AZ11: =AL7 -> 13.038875 | BA11: =AN7 -> 15.097645 | BB11: =AT11-AV11 -> 3.1698948e+08 | BC11: =AU11-AW11 -> 3.3384194e+08
B12: Year 2 | C12: =_xlfn.NORM.INV(RAND(),1500000,110000) -> 1600873.6 | F12: Year 1 | G12: =IF(RAND() < (13 - 8) / (18 - 8), 8 + SQRT(RAND()) * (13 - 8), 18 - SQRT(RAND()) * (18 - 13)) -> 14.255608 | L12: Year 6 | M12: =M11 * _xlfn.NORM.INV(RAND(), N3,N4) -> 203.65983 | S12: Year 3 | T12: =G14*$T$5 -> 14.876227 | U12: =G14*$U$5 -> 17.225105 | W12: Traditional | Z12: Modern | AC12: Year 7 | AD12: =IF(RAND() < 0.05, 1, 0) -> 0 | AF12: Year 7 | AG12: =IF(AD12=1, -LN(RAND()) / 5, 0) -> 0 | AI12: =IF(AD12=1, -LN(RAND()) / 10, 0) -> 0 | AK12: Year 7 | AL12: =T16 * (1 - AG12) -> 10.448539 | AN12: =U16 * (1 - AI12) -> 12.098309 | AS12: Year 3 | AT12: =MIN(AL8,M9) * C13 * 20 -> 4.6105959e+08 | AU12: =MIN(AN8,M9) * C13 * 20 -> 5.3385847e+08 | AV12: =$T$8 + X16 * 20 -> 92736904 | AW12: =$U$8+AA16 * 20 -> 1.4780721e+08 | AZ12: =AL8 -> 14.876227 | BA12: =AN8 -> 17.225105 | BB12: =AT12-AV12 -> 3.6832268e+08 | BC12: =AU12-AW12 -> 3.8605126e+08
B13: Year 3 | C13: =_xlfn.NORM.INV(RAND(),1500000,110000) -> 1549652.3 | F13: Year 2 | G13: =IF(RAND() < (13 - 8) / (18 - 8), 8 + SQRT(RAND()) * (13 - 8), 18 - SQRT(RAND()) * (18 - 13)) -> 13.725131 | L13: Year 7 | M13: =M12 * _xlfn.NORM.INV(RAND(), N3, N4) -> 234.1254 | S13: Year 4 | T13: =G15*$T$5 -> 11.703023 | U13: =G15*$U$5 -> 13.550869 | AC13: Year 8 | AD13: =IF(RAND() < 0.05, 1, 0) -> 0 | AF13: Year 8 | AG13: =IF(AD13=1, -LN(RAND()) / 5, 0) -> 0 | AI13: =IF(AD13=1, -LN(RAND()) / 10, 0) -> 0 | AK13: Year 8 | AL13: =T17 * (1 - AG13) -> 15.139465 | AN13: =U17 * (1 - AI13) -> 17.529906 | AS13: Year 4 | AT13: =MIN(AL9,M10) * C14 * 20 -> 3.2816413e+08 | AU13: =MIN(AN9,M10) * C14 * 20 -> 3.7997952e+08 | AV13: =$T$8 + X17 * 20 -> 1.0165328e+08 | AW13: =$U$8+AA17 * 20 -> 1.522217e+08 | AZ13: =AL9 -> 11.703023 | BA13: =AN9 -> 13.550869 | BB13: =AT13-AV13 -> 2.2651084e+08 | BC13: =AU13-AW13 -> 2.2775782e+08
B14: Year 4 | C14: =_xlfn.NORM.INV(RAND(),1500000,110000) -> 1402048.5 | F14: Year 3 | G14: =IF(RAND() < (13 - 8) / (18 - 8), 8 + SQRT(RAND()) * (13 - 8), 18 - SQRT(RAND()) * (18 - 13)) -> 15.659186 | L14: Year 8 | M14: =M13 * _xlfn.NORM.INV(RAND(), N3, N4) -> 239.84243 | S14: Year 5 | T14: =G16*$T$5 -> 14.693422 | U14: =G16*$U$5 -> 17.013436 | W14: Year 1 | X14: =_xlfn.LOGNORM.INV(RAND(),$X$7,$X$8) -> 1251511.4 | Z14: Year 1 | AA14: =_xlfn.LOGNORM.INV(RAND(),$AA$7,$AA$8) -> 1885315.3 | AC14: Year 9 | AD14: =IF(RAND() < 0.05, 1, 0) -> 0 | AF14: Year 9 | AG14: =IF(AD14=1, -LN(RAND()) / 5, 0) -> 0 | AI14: =IF(AD14=1, -LN(RAND()) / 10, 0) -> 0 | AK14: Year 9 | AL14: =T18 * (1 - AG14) -> 13.055747 | AN14: =U18 * (1 - AI14) -> 15.117181 | AS14: Year 5 | AT14: =MIN(AL10,M11) * C15 * 20 -> 4.5764426e+08 | AU14: =MIN(AN10,M11) * C15 * 20 -> 5.2990388e+08 | AV14: =$T$8 + X18 * 20 -> 92768170 | AW14: =$U$8+AA18 * 20 -> 1.5269522e+08 | AZ14: =AL10 -> 14.693422 | BA14: =AN10 -> 17.013436 | BB14: =AT14-AV14 -> 3.6487609e+08 | BC14: =AU14-AW14 -> 3.7720866e+08
B15: Year 5 | C15: =_xlfn.NORM.INV(RAND(),1500000,110000) -> 1557310 | F15: Year 4 | G15: =IF(RAND() < (13 - 8) / (18 - 8), 8 + SQRT(RAND()) * (13 - 8), 18 - SQRT(RAND()) * (18 - 13)) -> 12.318972 | L15: Year 9 | M15: =M14 * _xlfn.NORM.INV(RAND(), N3, N4) -> 246.30273 | S15: Year 6 | T15: =G17*$T$5 -> 10.676203 | U15: =G17*$U$5 -> 12.361919 | W15: Year 2 | X15: =_xlfn.LOGNORM.INV(RAND(),$X$7,$X$8) -> 1524116.1 | Z15: Year 2 | AA15: =_xlfn.LOGNORM.INV(RAND(),$AA$7,$AA$8) -> 1977323.3 | AC15: Year 10 | AD15: =IF(RAND() < 0.05, 1, 0) -> 1 | AF15: Year 10 | AG15: =IF(AD15=1, -LN(RAND()) / 5, 0) -> 0.10182146 | AI15: =IF(AD15=1, -LN(RAND()) / 10, 0) -> 0.11627212 | AK15: Year 10 | AL15: =T19 * (1 - AG15) -> 10.427167 | AN15: =U19 * (1 - AI15) -> 11.879312 | AS15: Year 6 | AT15: =MIN(AL11,M12) * C16 * 20 -> 2.7162392e+08 | AU15: =MIN(AN11,M12) * C16 * 20 -> 3.145119e+08 | AV15: =$T$8 + X19 * 20 -> 96455903 | AW15: =$U$8+AA19 * 20 -> 1.5131402e+08 | AZ15: =AL11 -> 10.676203 | BA15: =AN11 -> 12.361919 | BB15: =AT15-AV15 -> 1.7516801e+08 | BC15: =AU15-AW15 -> 1.6319788e+08
B16: Year 6 | C16: =_xlfn.NORM.INV(RAND(),1500000,110000) -> 1272099.8 | F16: Year 5 | G16: =IF(RAND() < (13 - 8) / (18 - 8), 8 + SQRT(RAND()) * (13 - 8), 18 - SQRT(RAND()) * (18 - 13)) -> 15.46676 | L16: Year 10 | M16: =M15 * _xlfn.NORM.INV(RAND(),N3,N4) -> 240.83044 | S16: Year 7 | T16: =G18*$T$5 -> 10.448539 | U16: =G18*$U$5 -> 12.098309 | W16: Year 3 | X16: =_xlfn.LOGNORM.INV(RAND(),$X$7,$X$8) -> 1136845.2 | Z16: Year 3 | AA16: =_xlfn.LOGNORM.INV(RAND(),$AA$7,$AA$8) -> 1890360.5 | AC16: Year 11 | AD16: =IF(RAND() < 0.05, 1, 0) -> 0 | AF16: Year 11 | AG16: =IF(AD16=1, -LN(RAND()) / 5, 0) -> 0 | AI16: =IF(AD16=1, -LN(RAND()) / 10, 0) -> 0 | AK16: Year 11 | AL16: =T20 * (1 - AG16) -> 15.136538 | AN16: =U20 * (1 - AI16) -> 17.526517 | AS16: Year 7 | AT16: =MIN(AL12,M13) * C17 * 20 -> 2.9072562e+08 | AU16: =MIN(AN12,M13) * C17 * 20 -> 3.3662966e+08 | AV16: =$T$8 + X20 * 20 -> 97367781 | AW16: =$U$8+AA20 * 20 -> 1.536483e+08 | AZ16: =AL12 -> 10.448539 | BA16: =AN12 -> 12.098309 | BB16: =AT16-AV16 -> 1.9335784e+08 | BC16: =AU16-AW16 -> 1.8298137e+08
B17: Year 7 | C17: =_xlfn.NORM.INV(RAND(),1500000,110000) -> 1391226.1 | F17: Year 6 | G17: =IF(RAND() < (13 - 8) / (18 - 8), 8 + SQRT(RAND()) * (13 - 8), 18 - SQRT(RAND()) * (18 - 13)) -> 11.238108 | L17: Year 11 | M17: =M16 * _xlfn.NORM.INV(RAND(),N3,N4) -> 239.49412 | S17: Year 8 | T17: =G19*$T$5 -> 15.139465 | U17: =G19*$U$5 -> 17.529906 | W17: Year 4 | X17: =_xlfn.LOGNORM.INV(RAND(),$X$7,$X$8) -> 1582664.2 | Z17: Year 4 | AA17: =_xlfn.LOGNORM.INV(RAND(),$AA$7,$AA$8) -> 2111084.9 | AC17: Year 12 | AD17: =IF(RAND() < 0.05, 1, 0) -> 0 | AF17: Year 12 | AG17: =IF(AD17=1, -LN(RAND()) / 5, 0) -> 0 | AI17: =IF(AD17=1, -LN(RAND()) / 10, 0) -> 0 | AK17: Year 12 | AL17: =T21 * (1 - AG17) -> 9.9041003 | AN17: =U21 * (1 - AI17) -> 11.467906 | AS17: Year 8 | AT17: =MIN(AL13,M14) * C18 * 20 -> 3.9228966e+08 | AU17: =MIN(AN13,M14) * C18 * 20 -> 4.5423013e+08 | AV17: =$T$8 + X21 * 20 -> 96366408 | AW17: =$U$8+AA21 * 20 -> 1.4749191e+08 | AZ17: =AL13 -> 15.139465 | BA17: =AN13 -> 17.529906 | BB17: =AT17-AV17 -> 2.9592325e+08 | BC17: =AU17-AW17 -> 3.0673822e+08
B18: Year 8 | C18: =_xlfn.NORM.INV(RAND(),1500000,110000) -> 1295586.3 | F18: Year 7 | G18: =IF(RAND() < (13 - 8) / (18 - 8), 8 + SQRT(RAND()) * (13 - 8), 18 - SQRT(RAND()) * (18 - 13)) -> 10.998462 | L18: Year 12 | M18: =M17 * _xlfn.NORM.INV(RAND(),N3,N4) -> 262.48667 | S18: Year 9 | T18: =G20*$T$5 -> 13.055747 | U18: =G20*$U$5 -> 15.117181 | W18: Year 5 | X18: =_xlfn.LOGNORM.INV(RAND(),$X$7,$X$8) -> 1138408.5 | Z18: Year 5 | AA18: =_xlfn.LOGNORM.INV(RAND(),$AA$7,$AA$8) -> 2134760.9 | AC18: Year 13 | AD18: =IF(RAND() < 0.05, 1, 0) -> 0 | AF18: Year 13 | AG18: =IF(AD18=1, -LN(RAND()) / 5, 0) -> 0 | AI18: =IF(AD18=1, -LN(RAND()) / 10, 0) -> 0 | AK18: Year 13 | AL18: =T22 * (1 - AG18) -> 8.0149548 | AN18: =U22 * (1 - AI18) -> 9.280474 | AS18: Year 9 | AT18: =MIN(AL14,M15) * C19 * 20 -> 3.9873593e+08 | AU18: =MIN(AN14,M15) * C19 * 20 -> 4.6169423e+08 | AV18: =$T$8 + X22 * 20 -> 93613401 | AW18: =$U$8+AA22 * 20 -> 1.4600329e+08 | AZ18: =AL14 -> 13.055747 | BA18: =AN14 -> 15.117181 | BB18: =AT18-AV18 -> 3.0512252e+08 | BC18: =AU18-AW18 -> 3.1569094e+08
B19: Year 9 | C19: =_xlfn.NORM.INV(RAND(),1500000,110000) -> 1527051.4 | F19: Year 8 | G19: =IF(RAND() < (13 - 8) / (18 - 8), 8 + SQRT(RAND()) * (13 - 8), 18 - SQRT(RAND()) * (18 - 13)) -> 15.936279 | L19: Year 13 | M19: =M18*_xlfn.NORM.INV(RAND(), N3,N4) -> 253.79627 | S19: Year 10 | T19: =G21*$T$5 -> 11.609236 | U19: =G21*$U$5 -> 13.442273 | W19: Year 6 | X19: =_xlfn.LOGNORM.INV(RAND(),$X$7,$X$8) -> 1322795.1 | Z19: Year 6 | AA19: =_xlfn.LOGNORM.INV(RAND(),$AA$7,$AA$8) -> 2065701.2 | AC19: Year 14 | AD19: =IF(RAND() < 0.05, 1, 0) -> 0 | AF19: Year 14 | AG19: =IF(AD19=1, -LN(RAND()) / 5, 0) -> 0 | AI19: =IF(AD19=1, -LN(RAND()) / 10, 0) -> 0 | AK19: Year 14 | AL19: =T23 * (1 - AG19) -> 14.446589 | AN19: =U23 * (1 - AI19) -> 16.72763 | AS19: Year 10 | AT19: =MIN(AL15,M16) * C20 * 20 -> 3.2320543e+08 | AU19: =MIN(AN15,M16) * C20 * 20 -> 3.682168e+08 | AV19: =$T$8 + X23 * 20 -> 90879640 | AW19: =$U$8+AA23 * 20 -> 1.473593e+08 | AZ19: =AL15 -> 10.427167 | BA19: =AN15 -> 11.879312 | BB19: =AT19-AV19 -> 2.3232579e+08 | BC19: =AU19-AW19 -> 2.2085751e+08
B20: Year 10 | C20: =_xlfn.NORM.INV(RAND(),1500000,110000) -> 1549823.8 | F20: Year 9 | G20: =IF(RAND() < (13 - 8) / (18 - 8), 8 + SQRT(RAND()) * (13 - 8), 18 - SQRT(RAND()) * (18 - 13)) -> 13.742891 | L20: Year 14 | M20: =M19 * _xlfn.NORM.INV(RAND(),N3,N4) -> 261.3982 | S20: Year 11 | T20: =G22*$T$5 -> 15.136538 | U20: =G22*$U$5 -> 17.526517 | W20: Year 7 | X20: =_xlfn.LOGNORM.INV(RAND(),$X$7,$X$8) -> 1368389.1 | Z20: Year 7 | AA20: =_xlfn.LOGNORM.INV(RAND(),$AA$7,$AA$8) -> 2182414.8 | AC20: Year 15 | AD20: =IF(RAND() < 0.05, 1, 0) -> 0 | AF20: Year 15 | AG20: =IF(AD20=1, -LN(RAND()) / 5, 0) -> 0 | AI20: =IF(AD20=1, -LN(RAND()) / 10, 0) -> 0 | AK20: Year 15 | AL20: =T24 * (1 - AG20) -> 13.786376 | AN20: =U24 * (1 - AI20) -> 15.963172 | AS20: Year 11 | AT20: =MIN(AL16,M17) * C21 * 20 -> 4.3152618e+08 | AU20: =MIN(AN16,M17) * C21 * 20 -> 4.9966189e+08 | AV20: =$T$8 + X24 * 20 -> 91496749 | AW20: =$U$8+AA24 * 20 -> 1.5496944e+08 | AZ20: =AL16 -> 15.136538 | BA20: =AN16 -> 17.526517 | BB20: =AT20-AV20 -> 3.4002943e+08 | BC20: =AU20-AW20 -> 3.4469245e+08
B21: Year 11 | C21: =_xlfn.NORM.INV(RAND(),1500000,110000) -> 1425445.5 | F21: Year 10 | G21: =IF(RAND() < (13 - 8) / (18 - 8), 8 + SQRT(RAND()) * (13 - 8), 18 - SQRT(RAND()) * (18 - 13)) -> 12.220249 | L21: Year 15 | M21: =M20 * _xlfn.NORM.INV(RAND(),N3,N4) -> 250.22929 | S21: Year 12 | T21: =G23*$T$5 -> 9.9041003 | U21: =G23*$U$5 -> 11.467906 | W21: Year 8 | X21: =_xlfn.LOGNORM.INV(RAND(),$X$7,$X$8) -> 1318320.4 | Z21: Year 8 | AA21: =_xlfn.LOGNORM.INV(RAND(),$AA$7,$AA$8) -> 1874595.5 | AC21: Year 16 | AD21: =IF(RAND() < 0.05, 1, 0) -> 0 | AF21: Year 16 | AG21: =IF(AD21=1, -LN(RAND()) / 5, 0) -> 0 | AI21: =IF(AD21=1, -LN(RAND()) / 10, 0) -> 0 | AK21: Year 16 | AL21: =T25 * (1 - AG21) -> 13.295829 | AN21: =U25 * (1 - AI21) -> 15.395171 | AS21: Year 12 | AT21: =MIN(AL17,M18) * C22 * 20 -> 2.8919465e+08 | AU21: =MIN(AN17,M18) * C22 * 20 -> 3.3485697e+08 | AV21: =$T$8 + X25 * 20 -> 97807152 | AW21: =$U$8+AA25 * 20 -> 1.4680743e+08 | AZ21: =AL17 -> 9.9041003 | BA21: =AN17 -> 11.467906 | BB21: =AT21-AV21 -> 1.913875e+08 | BC21: =AU21-AW21 -> 1.8804954e+08
B22: Year 12 | C22: =_xlfn.NORM.INV(RAND(),1500000,110000) -> 1459974.4 | F22: Year 11 | G22: =IF(RAND() < (13 - 8) / (18 - 8), 8 + SQRT(RAND()) * (13 - 8), 18 - SQRT(RAND()) * (18 - 13)) -> 15.933198 | L22: Year 16 | M22: =M21 * _xlfn.NORM.INV(RAND(), N3,N4) -> 243.225 | S22: Year 13 | T22: =G24*$T$5 -> 8.0149548 | U22: =G24*$U$5 -> 9.280474 | W22: Year 9 | X22: =_xlfn.LOGNORM.INV(RAND(),$X$7,$X$8) -> 1180670.1 | Z22: Year 9 | AA22: =_xlfn.LOGNORM.INV(RAND(),$AA$7,$AA$8) -> 1800164.7 | AC22: Year 17 | AD22: =IF(RAND() < 0.05, 1, 0) -> 0 | AF22: Year 17 | AG22: =IF(AD22=1, -LN(RAND()) / 5, 0) -> 0 | AI22: =IF(AD22=1, -LN(RAND()) / 10, 0) -> 0 | AK22: Year 17 | AL22: =T26 * (1 - AG22) -> 13.05661 | AN22: =U26 * (1 - AI22) -> 15.11818 | AS22: Year 13 | AT22: =MIN(AL18,M19) * C23 * 20 -> 3.0329659e+08 | AU22: =MIN(AN18,M19) * C23 * 20 -> 3.5118553e+08 | AV22: =$T$8 + X26 * 20 -> 95407710 | AW22: =$U$8+AA26 * 20 -> 1.4970074e+08 | AZ22: =AL18 -> 8.0149548 | BA22: =AN18 -> 9.280474 | BB22: =AT22-AV22 -> 2.0788888e+08 | BC22: =AU22-AW22 -> 2.0148478e+08
B23: Year 13 | C23: =_xlfn.NORM.INV(RAND(),1500000,110000) -> 1892066.7 | F23: Year 12 | G23: =IF(RAND() < (13 - 8) / (18 - 8), 8 + SQRT(RAND()) * (13 - 8), 18 - SQRT(RAND()) * (18 - 13)) -> 10.425369 | L23: Year 17 | M23: =M22 * _xlfn.NORM.INV(RAND(),N3,N4) -> 249.31482 | S23: Year 14 | T23: =G25*$T$5 -> 14.446589 | U23: =G25*$U$5 -> 16.72763 | W23: Year 10 | X23: =_xlfn.LOGNORM.INV(RAND(),$X$7,$X$8) -> 1043982 | Z23: Year 10 | AA23: =_xlfn.LOGNORM.INV(RAND(),$AA$7,$AA$8) -> 1867964.8 | AC23: Year 18 | AD23: =IF(RAND() < 0.05, 1, 0) -> 0 | AF23: Year 18 | AG23: =IF(AD23=1, -LN(RAND()) / 5, 0) -> 0 | AI23: =IF(AD23=1, -LN(RAND()) / 10, 0) -> 0 | AK23: Year 18 | AL23: =T27 * (1 - AG23) -> 10.64665 | AN23: =U27 * (1 - AI23) -> 12.327699 | AS23: Year 14 | AT23: =MIN(AL19,M20) * C24 * 20 -> 4.7287073e+08 | AU23: =MIN(AN19,M20) * C24 * 20 -> 5.4753453e+08 | AV23: =$T$8 + X27 * 20 -> 95101476 | AW23: =$U$8+AA27 * 20 -> 1.4976952e+08 | AZ23: =AL19 -> 14.446589 | BA23: =AN19 -> 16.72763 | BB23: =AT23-AV23 -> 3.7776926e+08 | BC23: =AU23-AW23 -> 3.9776502e+08
B24: Year 14 | C24: =_xlfn.NORM.INV(RAND(),1500000,110000) -> 1636617.2 | F24: Year 13 | G24: =IF(RAND() < (13 - 8) / (18 - 8), 8 + SQRT(RAND()) * (13 - 8), 18 - SQRT(RAND()) * (18 - 13)) -> 8.4367946 | L24: Year 18 | M24: =M23 * _xlfn.NORM.INV(RAND(),N3,N4) -> 252.59139 | S24: Year 15 | T24: =G26*$T$5 -> 13.786376 | U24: =G26*$U$5 -> 15.963172 | W24: Year 11 | X24: =_xlfn.LOGNORM.INV(RAND(),$X$7,$X$8) -> 1074837.5 | Z24: Year 11 | AA24: =_xlfn.LOGNORM.INV(RAND(),$AA$7,$AA$8) -> 2248471.8 | AC24: Year 19 | AD24: =IF(RAND() < 0.05, 1, 0) -> 0 | AF24: Year 19 | AG24: =IF(AD24=1, -LN(RAND()) / 5, 0) -> 0 | AI24: =IF(AD24=1, -LN(RAND()) / 10, 0) -> 0 | AK24: Year 19 | AL24: =T28 * (1 - AG24) -> 16.397948 | AN24: =U28 * (1 - AI24) -> 18.987098 | AS24: Year 15 | AT24: =MIN(AL20,M21) * C25 * 20 -> 4.6808069e+08 | AU24: =MIN(AN20,M21) * C25 * 20 -> 5.4198816e+08 | AV24: =$T$8 + X28 * 20 -> 95373959 | AW24: =$U$8+AA28 * 20 -> 1.4884917e+08 | AZ24: =AL20 -> 13.786376 | BA24: =AN20 -> 15.963172 | BB24: =AT24-AV24 -> 3.7270673e+08 | BC24: =AU24-AW24 -> 3.9313899e+08
B25: Year 15 | C25: =_xlfn.NORM.INV(RAND(),1500000,110000) -> 1697620.5 | F25: Year 14 | G25: =IF(RAND() < (13 - 8) / (18 - 8), 8 + SQRT(RAND()) * (13 - 8), 18 - SQRT(RAND()) * (18 - 13)) -> 15.206936 | L25: Year 19 | M25: =M24 * _xlfn.NORM.INV(RAND(),N3,N4) -> 240.51204 | S25: Year 16 | T25: =G27*$T$5 -> 13.295829 | U25: =G27*$U$5 -> 15.395171 | W25: Year 12 | X25: =_xlfn.LOGNORM.INV(RAND(),$X$7,$X$8) -> 1390357.6 | Z25: Year 12 | AA25: =_xlfn.LOGNORM.INV(RAND(),$AA$7,$AA$8) -> 1840371.4 | AC25: Year 20 | AD25: =IF(RAND() < 0.05, 1, 0) -> 0 | AF25: Year 20 | AG25: =IF(AD25=1, -LN(RAND()) / 5, 0) -> 0 | AI25: =IF(AD25=1, -LN(RAND()) / 10, 0) -> 0 | AK25: Year 20 | AL25: =T29 * (1 - AG25) -> 9.8049696 | AN25: =U29 * (1 - AI25) -> 11.353123 | AS25: Year 16 | AT25: =MIN(AL21,M22) * C26 * 20 -> 4.0887739e+08 | AU25: =MIN(AN21,M22) * C26 * 20 -> 4.7343697e+08 | AV25: =$T$8 + X29 * 20 -> 99427532 | AW25: =$U$8+AA29 * 20 -> 1.5095201e+08 | AZ25: =AL21 -> 13.295829 | BA25: =AN21 -> 15.395171 | BB25: =AT25-AV25 -> 3.0944985e+08 | BC25: =AU25-AW25 -> 3.2248496e+08
B26: Year 16 | C26: =_xlfn.NORM.INV(RAND(),1500000,110000) -> 1537615.2 | F26: Year 15 | G26: =IF(RAND() < (13 - 8) / (18 - 8), 8 + SQRT(RAND()) * (13 - 8), 18 - SQRT(RAND()) * (18 - 13)) -> 14.511974 | L26: Year 20 | M26: =M25 * _xlfn.NORM.INV(RAND(),N3,N4) -> 255.85265 | S26: Year 17 | T26: =G28*$T$5 -> 13.05661 | U26: =G28*$U$5 -> 15.11818 | W26: Year 13 | X26: =_xlfn.LOGNORM.INV(RAND(),$X$7,$X$8) -> 1270385.5 | Z26: Year 13 | AA26: =_xlfn.LOGNORM.INV(RAND(),$AA$7,$AA$8) -> 1985037.1 | AS26: Year 17 | AT26: =MIN(AL22,M23) * C27 * 20 -> 3.9269311e+08 | AU26: =MIN(AN22,M23) * C27 * 20 -> 4.5469728e+08 | AV26: =$T$8 + X30 * 20 -> 92802736 | AW26: =$U$8+AA30 * 20 -> 1.4673919e+08 | AZ26: =AL22 -> 13.05661 | BA26: =AN22 -> 15.11818 | BB26: =AT26-AV26 -> 2.9989037e+08 | BC26: =AU26-AW26 -> 3.0795809e+08
B27: Year 17 | C27: =_xlfn.NORM.INV(RAND(),1500000,110000) -> 1503809.6 | F27: Year 16 | G27: =IF(RAND() < (13 - 8) / (18 - 8), 8 + SQRT(RAND()) * (13 - 8), 18 - SQRT(RAND()) * (18 - 13)) -> 13.99561 | S27: Year 18 | T27: =G29*$T$5 -> 10.64665 | U27: =G29*$U$5 -> 12.327699 | W27: Year 14 | X27: =_xlfn.LOGNORM.INV(RAND(),$X$7,$X$8) -> 1255073.8 | Z27: Year 14 | AA27: =_xlfn.LOGNORM.INV(RAND(),$AA$7,$AA$8) -> 1988475.8 | AS27: Year 18 | AT27: =MIN(AL23,M24) * C28 * 20 -> 3.1073924e+08 | AU27: =MIN(AN23,M24) * C28 * 20 -> 3.5980333e+08 | AV27: =$T$8 + X31 * 20 -> 93326392 | AW27: =$U$8+AA31 * 20 -> 1.4898798e+08 | AZ27: =AL23 -> 10.64665 | BA27: =AN23 -> 12.327699 | BB27: =AT27-AV27 -> 2.1741285e+08 | BC27: =AU27-AW27 -> 2.1081535e+08
B28: Year 18 | C28: =_xlfn.NORM.INV(RAND(),1500000,110000) -> 1459328.8 | F28: Year 17 | G28: =IF(RAND() < (13 - 8) / (18 - 8), 8 + SQRT(RAND()) * (13 - 8), 18 - SQRT(RAND()) * (18 - 13)) -> 13.7438 | S28: Year 19 | T28: =G30*$T$5 -> 16.397948 | U28: =G30*$U$5 -> 18.987098 | W28: Year 15 | X28: =_xlfn.LOGNORM.INV(RAND(),$X$7,$X$8) -> 1268698 | Z28: Year 15 | AA28: =_xlfn.LOGNORM.INV(RAND(),$AA$7,$AA$8) -> 1942458.6 | AS28: Year 19 | AT28: =MIN(AL24,M25) * C29 * 20 -> 4.7980165e+08 | AU28: =MIN(AN24,M25) * C29 * 20 -> 5.555598e+08 | AV28: =$T$8 + X32 * 20 -> 92781866 | AW28: =$U$8+AA32 * 20 -> 1.4680235e+08 | AZ28: =AL24 -> 16.397948 | BA28: =AN24 -> 18.987098 | BB28: =AT28-AV28 -> 3.8701978e+08 | BC28: =AU28-AW28 -> 4.0875745e+08
B29: Year 19 | C29: =_xlfn.NORM.INV(RAND(),1500000,110000) -> 1462992.9 | F29: Year 18 | G29: =IF(RAND() < (13 - 8) / (18 - 8), 8 + SQRT(RAND()) * (13 - 8), 18 - SQRT(RAND()) * (18 - 13)) -> 11.207 | S29: Year 20 | T29: =G31*$T$5 -> 9.8049696 | U29: =G31*$U$5 -> 11.353123 | W29: Year 16 | X29: =_xlfn.LOGNORM.INV(RAND(),$X$7,$X$8) -> 1471376.6 | Z29: Year 16 | AA29: =_xlfn.LOGNORM.INV(RAND(),$AA$7,$AA$8) -> 2047600.4 | AS29: Year 20 | AT29: =MIN(AL25,M26) * C30 * 20 -> 3.0480893e+08 | AU29: =MIN(AN25,M26) * C30 * 20 -> 3.5293666e+08 | AV29: =$T$8 + X33 * 20 -> 98548775 | AW29: =$U$8+AA33 * 20 -> 1.5217447e+08 | AZ29: =AL25 -> 9.8049696 | BA29: =AN25 -> 11.353123 | BB29: =AT29-AV29 -> 2.0626016e+08 | BC29: =AU29-AW29 -> 2.0076219e+08
B30: Year 20 | C30: =_xlfn.NORM.INV(RAND(),1500000,110000) -> 1554359.4 | F30: Year 19 | G30: =IF(RAND() < (13 - 8) / (18 - 8), 8 + SQRT(RAND()) * (13 - 8), 18 - SQRT(RAND()) * (18 - 13)) -> 17.260998 | W30: Year 17 | X30: =_xlfn.LOGNORM.INV(RAND(),$X$7,$X$8) -> 1140136.8 | Z30: Year 17 | AA30: =_xlfn.LOGNORM.INV(RAND(),$AA$7,$AA$8) -> 1836959.7
F31: Year 20 | G31: =IF(RAND() < (13 - 8) / (18 - 8), 8 + SQRT(RAND()) * (13 - 8), 18 - SQRT(RAND()) * (18 - 13)) -> 10.321021 | W31: Year 18 | X31: =_xlfn.LOGNORM.INV(RAND(),$X$7,$X$8) -> 1166319.6 | Z31: Year 18 | AA31: =_xlfn.LOGNORM.INV(RAND(),$AA$7,$AA$8) -> 1949398.9
W32: Year 19 | X32: =_xlfn.LOGNORM.INV(RAND(),$X$7,$X$8) -> 1139093.3 | Z32: Year 19 | AA32: =_xlfn.LOGNORM.INV(RAND(),$AA$7,$AA$8) -> 1840117.6
W33: Year 20 | X33: =_xlfn.LOGNORM.INV(RAND(),$X$7,$X$8) -> 1427438.8 | Z33: Year 20 | AA33: =_xlfn.LOGNORM.INV(RAND(),$AA$7,$AA$8) -> 2108723.6

Sheet Varity B - Cabarnet Savignon
B2: Varity B - Cabarnet Savignon | Q2: Material costs per hectar | W2: Disese occurance | Z2: Exponential distribution | AF2: Adjusting yield to deases risk
Q3: Traditinal farming | T3: Modern farming | W3: 5 % probability of occuring each year | Z3: Traditonal | AC3: Modern | AF3: Traditional | AH3: Modern
B4: Annual Yield | C4: Triangular distribution | F4: Price per ton | G4: Normal distribution | J4: Annual demand | K4: Normal distribution | N4: Farming tecniques: | Q4: Mean | R4: CLP 1 600 000,00 | T4: Mean | U4: 2500000 | W4: 0 if it dosent occure, 1 if it does | Z4: Lambda | AA4: 5 | AC4: 10
N5: Traditional farming | O5: Modern farming | Q5: STD | R5: CLP 200 000,00 | T5: STD | U5: 180000 | Z5: Average | AA5: 0.1 | AC5: 0.2 | AN5: Annual revenue | AP5: Costs | AR5: Disease events | AT5: Yield | AV5: Profit per year
B6: Min | C6: 5 | F6: Mean | G6: 1900000 | J6: Mean | K6: STD | M6: Annual fixed cost per hectar | N6: 3500000 | O6: 5500000 | W6: Year 1 | X6: =IF(RAND() < 0.05, 1, 0) -> 0
B7: Most likely | C7: 10 | F7: STD | G7: 250000 | J7: 0.985 | K7: 0.04 | M7: Effect on the annual yield in percentage | N7: 0.95 | O7: 1.1 | Q7: Scaled mean | R7: 14.27 | T7: Scaled mean | U7: 14.73 | W7: Year 2 | X7: =IF(RAND() < 0.05, 1, 0) -> 0 | Z7: Year 1 | AA7: =IF(X6=1, -LN(RAND()) / 5, 0) -> 0 | AC7: =IF(X6=1, -LN(RAND()) / 10, 0) -> 0 | AE7: Year 1 | AF7: =N12 * (1 - AA7) -> 11.883303 | AH7: =O12 * (1 - AC7) -> 13.759614
B8: Max | C8: 14 | M8: Total hectar per year | N8: 20 | O8: 20 | Q8: Scaled STD | R8: 0.124 | T8: Scaled STD | U8: 0.071 | W8: Year 3 | X8: =IF(RAND() < 0.05, 1, 0) -> 0 | Z8: Year 2 | AA8: =IF(X7=1, -LN(RAND()) / 5, 0) -> 0 | AC8: =IF(X7=1, -LN(RAND()) / 10, 0) -> 0 | AE8: Year 2 | AF8: =N13 * (1 - AA8) -> 10.728738 | AH8: =O13 * (1 - AC8) -> 12.422749
W9: Year 4 | X9: =IF(RAND() < 0.05, 1, 0) -> 0 | Z9: Year 3 | AA9: =IF(X8=1, -LN(RAND()) / 5, 0) -> 0 | AC9: =IF(X8=1, -LN(RAND()) / 10, 0) -> 0 | AE9: Year 3 | AF9: =N14 * (1 - AA9) -> 10.799913 | AH9: =O14 * (1 - AC9) -> 12.505162
B10: Year 1 | C10: =IF(RAND() < (10-5)/(14-5), 5 + SQRT(RAND() * (10-5) * (14-5)), 14 - SQRT((1-RAND()) * (14-10) * (14-5))) -> 12.50874 | F10: Year 1 | G10: =_xlfn.NORM.INV(RAND(),1900000,250000) -> 1678366.3 | I10: Year 1 | J10: 180 | M10: Fixed cost per year | N10: =N6*N8 -> 70000000 | O10: =O6*O8 -> 110000000 | W10: Year 5 | X10: =IF(RAND() < 0.05, 1, 0) -> 0 | Z10: Year 4 | AA10: =IF(X9=1, -LN(RAND()) / 5, 0) -> 0 | AC10: =IF(X9=1, -LN(RAND()) / 10, 0) -> 0 | AE10: Year 4 | AF10: =N15 * (1 - AA10) -> 7.9795886 | AH10: =O15 * (1 - AC10) -> 9.2395237
B11: Year 2 | C11: =IF(RAND() < (10-5)/(14-5), 5 + SQRT(RAND() * (10-5) * (14-5)), 14 - SQRT((1-RAND()) * (14-10) * (14-5))) -> 11.293408 | F11: Year 2 | G11: =_xlfn.NORM.INV(RAND(),1900000,250000) -> 1871125.8 | I11: Year 2 | J11: =J10 * _xlfn.NORM.INV(RAND(),$J$7,$K$7) -> 184.12717 | N11: Adjusted yield traditional | O11: Adjusted yield modern | W11: Year 6 | X11: =IF(RAND() < 0.05, 1, 0) -> 0 | Z11: Year 5 | AA11: =IF(X10=1, -LN(RAND()) / 5, 0) -> 0 | AC11: =IF(X10=1, -LN(RAND()) / 10, 0) -> 0 | AE11: Year 5 | AF11: =N16 * (1 - AA11) -> 9.0516924 | AH11: =O16 * (1 - AC11) -> 10.480907 | AN11: Traditional | AO11: Modern | AP11: Traditonal | AQ11: Modern | AR11: Traditional | AS11: Modern | AT11: Traditional | AU11: Modern | AV11: Traditonal | AW11: Modern
B12: Year 3 | C12: =IF(RAND() < (10-5)/(14-5), 5 + SQRT(RAND() * (10-5) * (14-5)), 14 - SQRT((1-RAND()) * (14-10) * (14-5))) -> 11.368329 | F12: Year 3 | G12: =_xlfn.NORM.INV(RAND(),1900000,250000) -> 2421909 | I12: Year 3 | J12: =J11 * _xlfn.NORM.INV(RAND(),$J$7,$K$7) -> 186.23002 | M12: Year 1 | N12: =C10*$N$7 -> 11.883303 | O12: =C10*$O$7 -> 13.759614 | Q12: Year 1 | R12: =_xlfn.LOGNORM.INV(RAND(),$R$7,$R$8) -> 1376102.5 | T12: Year 1 | U12: =_xlfn.LOGNORM.INV(RAND(),$U$7,$U$8) -> 2520503.1 | W12: Year 7 | X12: =IF(RAND() < 0.05, 1, 0) -> 0 | Z12: Year 6 | AA12: =IF(X11=1, -LN(RAND()) / 5, 0) -> 0 | AC12: =IF(X11=1, -LN(RAND()) / 10, 0) -> 0 | AE12: Year 6 | AF12: =N17 * (1 - AA12) -> 8.8855182 | AH12: =O17 * (1 - AC12) -> 10.288495 | AM12: Year 1 | AN12: =MIN(AF7,J10) * G10 * 20 -> 3.988907e+08 | AO12: =MIN(AH7,J10) * G10 * 20 -> 4.6187344e+08 | AP12: =$N$10 + R12 * 20 -> 97522050 | AQ12: =$O$10 + U12 * 20 -> 1.6041006e+08 | AR12: =SUM(X6:X25) -> 4 | AS12: =SUM(X6:X25) -> 4 | AT12: =AF7 -> 11.883303 | AU12: =AH7 -> 13.759614 | AV12: =AN12 - AP12 -> 3.0136865e+08 | AW12: =AO12 - AQ12 -> 3.0146338e+08
B13: Year 4 | C13: =IF(RAND() < (10-5)/(14-5), 5 + SQRT(RAND() * (10-5) * (14-5)), 14 - SQRT((1-RAND()) * (14-10) * (14-5))) -> 8.399567 | F13: Year 4 | G13: =_xlfn.NORM.INV(RAND(),1900000,250000) -> 1924355.7 | I13: Year 4 | J13: =J12 * _xlfn.NORM.INV(RAND(),$J$7,$K$7) -> 178.86942 | M13: Year 2 | N13: =C11*$N$7 -> 10.728738 | O13: =C11*$O$7 -> 12.422749 | Q13: Year 2 | R13: =_xlfn.LOGNORM.INV(RAND(),$R$7,$R$8) -> 1356954.6 | T13: Year 2 | U13: =_xlfn.LOGNORM.INV(RAND(),$U$7,$U$8) -> 2754808.9 | W13: Year 8 | X13: =IF(RAND() < 0.05, 1, 0) -> 0 | Z13: Year 7 | AA13: =IF(X12=1, -LN(RAND()) / 5, 0) -> 0 | AC13: =IF(X12=1, -LN(RAND()) / 10, 0) -> 0 | AE13: Year 7 | AF13: =N18 * (1 - AA13) -> 10.215445 | AH13: =O18 * (1 - AC13) -> 11.82841 | AM13: Year 2 | AN13: =MIN(AF8,J11) * G11 * 20 -> 4.0149636e+08 | AO13: =MIN(AH8,J11) * G11 * 20 -> 4.6489052e+08 | AP13: =$N$10 + R13 * 20 -> 97139092 | AQ13: =$O$10 + U13 * 20 -> 1.6509618e+08 | AT13: =AF8 -> 10.728738 | AU13: =AH8 -> 12.422749 | AV13: =AN13-AP13 -> 3.0435726e+08 | AW13: =AO13-AQ13 -> 2.9979434e+08
B14: Year 5 | C14: =IF(RAND() < (10-5)/(14-5), 5 + SQRT(RAND() * (10-5) * (14-5)), 14 - SQRT((1-RAND()) * (14-10) * (14-5))) -> 9.5280972 | F14: Year 5 | G14: =_xlfn.NORM.INV(RAND(),1900000,250000) -> 1736220.1 | I14: Year 5 | J14: =J13 * _xlfn.NORM.INV(RAND(),$J$7,$K$7) -> 186.8964 | M14: Year 3 | N14: =C12*$N$7 -> 10.799913 | O14: =C12*$O$7 -> 12.505162 | Q14: Year 3 | R14: =_xlfn.LOGNORM.INV(RAND(),$R$7,$R$8) -> 1793790.7 | T14: Year 3 | U14: =_xlfn.LOGNORM.INV(RAND(),$U$7,$U$8) -> 2473500.5 | W14: Year 9 | X14: =IF(RAND() < 0.05, 1, 0) -> 1 | Z14: Year 8 | AA14: =IF(X13=1, -LN(RAND()) / 5, 0) -> 0 | AC14: =IF(X13=1, -LN(RAND()) / 10, 0) -> 0 | AE14: Year 8 | AF14: =N19 * (1 - AA14) -> 9.0799509 | AH14: =O19 * (1 - AC14) -> 10.513627 | AM14: Year 3 | AN14: =MIN(AF9,J12) * G12 * 20 -> 5.2312813e+08 | AO14: =MIN(AH9,J12) * G12 * 20 -> 6.0572731e+08 | AP14: =$N$10 + R14 * 20 -> 1.0587581e+08 | AQ14: =$O$10 + U14 * 20 -> 1.5947001e+08 | AT14: =AF9 -> 10.799913 | AU14: =AH9 -> 12.505162 | AV14: =AN14-AP14 -> 4.1725232e+08 | AW14: =AO14-AQ14 -> 4.462573e+08
B15: Year 6 | C15: =IF(RAND() < (10-5)/(14-5), 5 + SQRT(RAND() * (10-5) * (14-5)), 14 - SQRT((1-RAND()) * (14-10) * (14-5))) -> 9.353177 | F15: Year 6 | G15: =_xlfn.NORM.INV(RAND(),1900000,250000) -> 1840769.2 | I15: Year 6 | J15: =J14 * _xlfn.NORM.INV(RAND(),$J$7,$K$7) -> 185.07071 | M15: Year 4 | N15: =C13*$N$7 -> 7.9795886 | O15: =C13*$O$7 -> 9.2395237 | Q15: Year 4 | R15: =_xlfn.LOGNORM.INV(RAND(),$R$7,$R$8) -> 1520825.5 | T15: Year 4 | U15: =_xlfn.LOGNORM.INV(RAND(),$U$7,$U$8) -> 2249378.8 | W15: Year 10 | X15: =IF(RAND() < 0.05, 1, 0) -> 0 | Z15: Year 9 | AA15: =IF(X14=1, -LN(RAND()) / 5, 0) -> 0.31484033 | AC15: =IF(X14=1, -LN(RAND()) / 10, 0) -> 0.10504025 | AE15: Year 9 | AF15: =N20 * (1 - AA15) -> 5.647545 | AH15: =O20 * (1 - AC15) -> 8.5416249 | AM15: Year 4 | AN15: =MIN(AF10,J13) * G13 * 20 -> 3.0711133e+08 | AO15: =MIN(AH10,J13) * G13 * 20 -> 3.556026e+08 | AP15: =$N$10 + R15 * 20 -> 1.0041651e+08 | AQ15: =$O$10 + U15 * 20 -> 1.5498758e+08 | AT15: =AF10 -> 7.9795886 | AU15: =AH10 -> 9.2395237 | AV15: =AN15-AP15 -> 2.0669482e+08 | AW15: =AO15-AQ15 -> 2.0061502e+08
B16: Year 7 | C16: =IF(RAND() < (10-5)/(14-5), 5 + SQRT(RAND() * (10-5) * (14-5)), 14 - SQRT((1-RAND()) * (14-10) * (14-5))) -> 10.7531 | F16: Year 7 | G16: =_xlfn.NORM.INV(RAND(),1900000,250000) -> 1700822.9 | I16: Year 7 | J16: =J15 * _xlfn.NORM.INV(RAND(),$J$7,$K$7) -> 185.19257 | M16: Year 5 | N16: =C14*$N$7 -> 9.0516924 | O16: =C14*$O$7 -> 10.480907 | Q16: Year 5 | R16: =_xlfn.LOGNORM.INV(RAND(),$R$7,$R$8) -> 1530531.1 | T16: Year 5 | U16: =_xlfn.LOGNORM.INV(RAND(),$U$7,$U$8) -> 2344967.9 | W16: Year 11 | X16: =IF(RAND() < 0.05, 1, 0) -> 0 | Z16: Year 10 | AA16: =IF(X15=1, -LN(RAND()) / 5, 0) -> 0 | AC16: =IF(X15=1, -LN(RAND()) / 10, 0) -> 0 | AE16: Year 10 | AF16: =N21 * (1 - AA16) -> 5.5296099 | AH16: =O21 * (1 - AC16) -> 6.4027062 | AM16: Year 5 | AN16: =MIN(AF11,J14) * G14 * 20 -> 3.1431461e+08 | AO16: =MIN(AH11,J14) * G14 * 20 -> 3.6394323e+08 | AP16: =$N$10 + R16 * 20 -> 1.0061062e+08 | AQ16: =$O$10 + U16 * 20 -> 1.5689936e+08 | AT16: =AF11 -> 9.0516924 | AU16: =AH11 -> 10.480907 | AV16: =AN16-AP16 -> 2.1370399e+08 | AW16: =AO16-AQ16 -> 2.0704387e+08
B17: Year 8 | C17: =IF(RAND() < (10-5)/(14-5), 5 + SQRT(RAND() * (10-5) * (14-5)), 14 - SQRT((1-RAND()) * (14-10) * (14-5))) -> 9.5578431 | F17: Year 8 | G17: =_xlfn.NORM.INV(RAND(),1900000,250000) -> 1869133.8 | I17: Year 8 | J17: =J16 * _xlfn.NORM.INV(RAND(),$J$7,$K$7) -> 180.25862 | M17: Year 6 | N17: =C15*$N$7 -> 8.8855182 | O17: =C15*$O$7 -> 10.288495 | Q17: Year 6 | R17: =_xlfn.LOGNORM.INV(RAND(),$R$7,$R$8) -> 1709959.3 | T17: Year 6 | U17: =_xlfn.LOGNORM.INV(RAND(),$U$7,$U$8) -> 2178890 | W17: Year 12 | X17: =IF(RAND() < 0.05, 1, 0) -> 0 | Z17: Year 11 | AA17: =IF(X16=1, -LN(RAND()) / 5, 0) -> 0 | AC17: =IF(X16=1, -LN(RAND()) / 10, 0) -> 0 | AE17: Year 11 | AF17: =N22 * (1 - AA17) -> 7.6698654 | AH17: =O22 * (1 - AC17) -> 8.8808968 | AM17: Year 6 | AN17: =MIN(AF12,J15) * G15 * 20 -> 3.2712377e+08 | AO17: =MIN(AH12,J15) * G15 * 20 -> 3.7877489e+08 | AP17: =$N$10 + R17 * 20 -> 1.0419919e+08 | AQ17: =$O$10 + U17 * 20 -> 1.535778e+08 | AT17: =AF12 -> 8.8855182 | AU17: =AH12 -> 10.288495 | AV17: =AN17-AP17 -> 2.2292459e+08 | AW17: =AO17-AQ17 -> 2.2519709e+08
B18: Year 9 | C18: =IF(RAND() < (10-5)/(14-5), 5 + SQRT(RAND() * (10-5) * (14-5)), 14 - SQRT((1-RAND()) * (14-10) * (14-5))) -> 8.6764947 | F18: Year 9 | G18: =_xlfn.NORM.INV(RAND(),1900000,250000) -> 2398732.1 | I18: Year 9 | J18: =J17 * _xlfn.NORM.INV(RAND(),$J$7,$K$7) -> 173.61968 | M18: Year 7 | N18: =C16*$N$7 -> 10.215445 | O18: =C16*$O$7 -> 11.82841 | Q18: Year 7 | R18: =_xlfn.LOGNORM.INV(RAND(),$R$7,$R$8) -> 1409333.8 | T18: Year 7 | U18: =_xlfn.LOGNORM.INV(RAND(),$U$7,$U$8) -> 2829888.3 | W18: Year 13 | X18: =IF(RAND() < 0.05, 1, 0) -> 0 | Z18: Year 12 | AA18: =IF(X17=1, -LN(RAND()) / 5, 0) -> 0 | AC18: =IF(X17=1, -LN(RAND()) / 10, 0) -> 0 | AE18: Year 12 | AF18: =N23 * (1 - AA18) -> 8.8388759 | AH18: =O23 * (1 - AC18) -> 10.234488 | AM18: Year 7 | AN18: =MIN(AF13,J16) * G16 * 20 -> 3.4749326e+08 | AO18: =MIN(AH13,J16) * G16 * 20 -> 4.0236062e+08 | AP18: =$N$10 + R18 * 20 -> 98186675 | AQ18: =$O$10 + U18 * 20 -> 1.6659777e+08 | AT18: =AF13 -> 10.215445 | AU18: =AH13 -> 11.82841 | AV18: =AN18-AP18 -> 2.4930659e+08 | AW18: =AO18-AQ18 -> 2.3576285e+08
B19: Year 10 | C19: =IF(RAND() < (10-5)/(14-5), 5 + SQRT(RAND() * (10-5) * (14-5)), 14 - SQRT((1-RAND()) * (14-10) * (14-5))) -> 5.820642 | F19: Year 10 | G19: =_xlfn.NORM.INV(RAND(),1900000,250000) -> 1901940.4 | I19: Year 10 | J19: =J18 * _xlfn.NORM.INV(RAND(),$J$7,$K$7) -> 184.02845 | M19: Year 8 | N19: =C17*$N$7 -> 9.0799509 | O19: =C17*$O$7 -> 10.513627 | Q19: Year 8 | R19: =_xlfn.LOGNORM.INV(RAND(),$R$7,$R$8) -> 1594106 | T19: Year 8 | U19: =_xlfn.LOGNORM.INV(RAND(),$U$7,$U$8) -> 2435652.2 | W19: Year 14 | X19: =IF(RAND() < 0.05, 1, 0) -> 0 | Z19: Year 13 | AA19: =IF(X18=1, -LN(RAND()) / 5, 0) -> 0 | AC19: =IF(X18=1, -LN(RAND()) / 10, 0) -> 0 | AE19: Year 13 | AF19: =N24 * (1 - AA19) -> 8.842148 | AH19: =O24 * (1 - AC19) -> 10.238277 | AM19: Year 8 | AN19: =MIN(AF14,J17) * G17 * 20 -> 3.3943287e+08 | AO19: =MIN(AH14,J17) * G17 * 20 -> 3.9302753e+08 | AP19: =$N$10 + R19 * 20 -> 1.0188212e+08 | AQ19: =$O$10 + U19 * 20 -> 1.5871304e+08 | AT19: =AF14 -> 9.0799509 | AU19: =AH14 -> 10.513627 | AV19: =AN19-AP19 -> 2.3755075e+08 | AW19: =AO19-AQ19 -> 2.3431449e+08
B20: Year 11 | C20: =IF(RAND() < (10-5)/(14-5), 5 + SQRT(RAND() * (10-5) * (14-5)), 14 - SQRT((1-RAND()) * (14-10) * (14-5))) -> 8.0735426 | F20: Year 11 | G20: =_xlfn.NORM.INV(RAND(),1900000,250000) -> 1828089 | I20: Year 11 | J20: =J19 * _xlfn.NORM.INV(RAND(),$J$7,$K$7) -> 187.03368 | M20: Year 9 | N20: =C18*$N$7 -> 8.24267 | O20: =C18*$O$7 -> 9.5441442 | Q20: Year 9 | R20: =_xlfn.LOGNORM.INV(RAND(),$R$7,$R$8) -> 1387495 | T20: Year 9 | U20: =_xlfn.LOGNORM.INV(RAND(),$U$7,$U$8) -> 2247921.9 | W20: Year 15 | X20: =IF(RAND() < 0.05, 1, 0) -> 0 | Z20: Year 14 | AA20: =IF(X19=1, -LN(RAND()) / 5, 0) -> 0 | AC20: =IF(X19=1, -LN(RAND()) / 10, 0) -> 0 | AE20: Year 14 | AF20: =N25 * (1 - AA20) -> 6.3438678 | AH20: =O25 * (1 - AC20) -> 7.3455311 | AM20: Year 9 | AN20: =MIN(AF15,J18) * G18 * 20 -> 2.7093895e+08 | AO20: =MIN(AH15,J18) * G18 * 20 -> 4.0978139e+08 | AP20: =$N$10 + R20 * 20 -> 97749900 | AQ20: =$O$10 + U20 * 20 -> 1.5495844e+08 | AT20: =AF15 -> 5.647545 | AU20: =AH15 -> 8.5416249 | AV20: =AN20-AP20 -> 1.7318905e+08 | AW20: =AO20-AQ20 -> 2.5482296e+08
B21: Year 12 | C21: =IF(RAND() < (10-5)/(14-5), 5 + SQRT(RAND() * (10-5) * (14-5)), 14 - SQRT((1-RAND()) * (14-10) * (14-5))) -> 9.3040798 | F21: Year 12 | G21: =_xlfn.NORM.INV(RAND(),1900000,250000) -> 2157967.3 | I21: Year 12 | J21: =J20 * _xlfn.NORM.INV(RAND(),$J$7,$K$7) -> 189.28968 | M21: Year 10 | N21: =C19*$N$7 -> 5.5296099 | O21: =C19*$O$7 -> 6.4027062 | Q21: Year 10 | R21: =_xlfn.LOGNORM.INV(RAND(),$R$7,$R$8) -> 1889676.2 | T21: Year 10 | U21: =_xlfn.LOGNORM.INV(RAND(),$U$7,$U$8) -> 2523359.5 | W21: Year 16 | X21: =IF(RAND() < 0.05, 1, 0) -> 0 | Z21: Year 15 | AA21: =IF(X20=1, -LN(RAND()) / 5, 0) -> 0 | AC21: =IF(X20=1, -LN(RAND()) / 10, 0) -> 0 | AE21: Year 15 | AF21: =N26 * (1 - AA21) -> 10.825104 | AH21: =O26 * (1 - AC21) -> 12.534331 | AM21: Year 10 | AN21: =MIN(AF16,J19) * G19 * 20 -> 2.1033977e+08 | AO21: =MIN(AH16,J19) * G19 * 20 -> 2.4355131e+08 | AP21: =$N$10 + R21 * 20 -> 1.0779352e+08 | AQ21: =$O$10 + U21 * 20 -> 1.6046719e+08 | AT21: =AF16 -> 5.5296099 | AU21: =AH16 -> 6.4027062 | AV21: =AN21-AP21 -> 1.0254625e+08 | AW21: =AO21-AQ21 -> 83084123
B22: Year 13 | C22: =IF(RAND() < (10-5)/(14-5), 5 + SQRT(RAND() * (10-5) * (14-5)), 14 - SQRT((1-RAND()) * (14-10) * (14-5))) -> 9.3075242 | F22: Year 13 | G22: =_xlfn.NORM.INV(RAND(),1900000,250000) -> 2147057.2 | I22: Year 13 | J22: =J21 * _xlfn.NORM.INV(RAND(),$J$7,$K$7) -> 193.5206 | M22: Year 11 | N22: =C20*$N$7 -> 7.6698654 | O22: =C20*$O$7 -> 8.8808968 | Q22: Year 11 | R22: =_xlfn.LOGNORM.INV(RAND(),$R$7,$R$8) -> 1856223 | T22: Year 11 | U22: =_xlfn.LOGNORM.INV(RAND(),$U$7,$U$8) -> 2672303.8 | W22: Year 17 | X22: =IF(RAND() < 0.05, 1, 0) -> 1 | Z22: Year 16 | AA22: =IF(X21=1, -LN(RAND()) / 5, 0) -> 0 | AC22: =IF(X21=1, -LN(RAND()) / 10, 0) -> 0 | AE22: Year 16 | AF22: =N27 * (1 - AA22) -> 7.4736064 | AH22: =O27 * (1 - AC22) -> 8.6536496 | AM22: Year 11 | AN22: =MIN(AF17,J20) * G20 * 20 -> 2.8042394e+08 | AO22: =MIN(AH17,J20) * G20 * 20 -> 3.247014e+08 | AP22: =$N$10 + R22 * 20 -> 1.0712446e+08 | AQ22: =$O$10 + U22 * 20 -> 1.6344608e+08 | AT22: =AF17 -> 7.6698654 | AU22: =AH17 -> 8.8808968 | AV22: =AN22-AP22 -> 1.7329948e+08 | AW22: =AO22-AQ22 -> 1.6125533e+08
B23: Year 14 | C23: =IF(RAND() < (10-5)/(14-5), 5 + SQRT(RAND() * (10-5) * (14-5)), 14 - SQRT((1-RAND()) * (14-10) * (14-5))) -> 6.6777556 | F23: Year 14 | G23: =_xlfn.NORM.INV(RAND(),1900000,250000) -> 1699265.1 | I23: Year 14 | J23: =J22 * _xlfn.NORM.INV(RAND(),$J$7,$K$7) -> 201.97498 | M23: Year 12 | N23: =C21*$N$7 -> 8.8388759 | O23: =C21*$O$7 -> 10.234488 | Q23: Year 12 | R23: =_xlfn.LOGNORM.INV(RAND(),$R$7,$R$8) -> 1566284.6 | T23: Year 12 | U23: =_xlfn.LOGNORM.INV(RAND(),$U$7,$U$8) -> 2597150.2 | W23: Year 18 | X23: =IF(RAND() < 0.05, 1, 0) -> 0 | Z23: Year 17 | AA23: =IF(X22=1, -LN(RAND()) / 5, 0) -> 0.39179413 | AC23: =IF(X22=1, -LN(RAND()) / 10, 0) -> 0.045419812 | AE23: Year 17 | AF23: =N28 * (1 - AA23) -> 4.5310586 | AH23: =O28 * (1 - AC23) -> 8.2343736 | AM23: Year 12 | AN23: =MIN(AF18,J21) * G21 * 20 -> 3.814801e+08 | AO23: =MIN(AH18,J21) * G21 * 20 -> 4.417138e+08 | AP23: =$N$10 + R23 * 20 -> 1.0132569e+08 | AQ23: =$O$10 + U23 * 20 -> 1.61943e+08 | AT23: =AF18 -> 8.8388759 | AU23: =AH18 -> 10.234488 | AV23: =AN23-AP23 -> 2.8015441e+08 | AW23: =AO23-AQ23 -> 2.797708e+08
B24: Year 15 | C24: =IF(RAND() < (10-5)/(14-5), 5 + SQRT(RAND() * (10-5) * (14-5)), 14 - SQRT((1-RAND()) * (14-10) * (14-5))) -> 11.394846 | F24: Year 15 | G24: =_xlfn.NORM.INV(RAND(),1900000,250000) -> 1660387.5 | I24: Year 15 | J24: =J23 * _xlfn.NORM.INV(RAND(),$J$7,$K$7) -> 212.44734 | M24: Year 13 | N24: =C22*$N$7 -> 8.842148 | O24: =C22*$O$7 -> 10.238277 | Q24: Year 13 | R24: =_xlfn.LOGNORM.INV(RAND(),$R$7,$R$8) -> 1383968.8 | T24: Year 13 | U24: =_xlfn.LOGNORM.INV(RAND(),$U$7,$U$8) -> 2585967.5 | W24: Year 19 | X24: =IF(RAND() < 0.05, 1, 0) -> 1 | Z24: Year 18 | AA24: =IF(X23=1, -LN(RAND()) / 5, 0) -> 0 | AC24: =IF(X23=1, -LN(RAND()) / 10, 0) -> 0 | AE24: Year 18 | AF24: =N29 * (1 - AA24) -> 9.9500616 | AH24: =O29 * (1 - AC24) -> 11.521124 | AM24: Year 13 | AN24: =MIN(AF19,J22) * G22 * 20 -> 3.7969194e+08 | AO24: =MIN(AH19,J22) * G22 * 20 -> 4.396433e+08 | AP24: =$N$10 + R24 * 20 -> 97679375 | AQ24: =$O$10 + U24 * 20 -> 1.6171935e+08 | AT24: =AF19 -> 8.842148 | AU24: =AH19 -> 10.238277 | AV24: =AN24-AP24 -> 2.8201257e+08 | AW24: =AO24-AQ24 -> 2.7792395e+08
B25: Year 16 | C25: =IF(RAND() < (10-5)/(14-5), 5 + SQRT(RAND() * (10-5) * (14-5)), 14 - SQRT((1-RAND()) * (14-10) * (14-5))) -> 7.8669542 | F25: Year 16 | G25: =_xlfn.NORM.INV(RAND(),1900000,250000) -> 1815007.6 | I25: Year 16 | J25: =J24 * _xlfn.NORM.INV(RAND(),$J$7,$K$7) -> 206.4997 | M25: Year 14 | N25: =C23*$N$7 -> 6.3438678 | O25: =C23*$O$7 -> 7.3455311 | Q25: Year 14 | R25: =_xlfn.LOGNORM.INV(RAND(),$R$7,$R$8) -> 1145436.9 | T25: Year 14 | U25: =_xlfn.LOGNORM.INV(RAND(),$U$7,$U$8) -> 2452234.6 | W25: Year 20 | X25: =IF(RAND() < 0.05, 1, 0) -> 1 | Z25: Year 19 | AA25: =IF(X24=1, -LN(RAND()) / 5, 0) -> 0.26801312 | AC25: =IF(X24=1, -LN(RAND()) / 10, 0) -> 0.02560492 | AE25: Year 19 | AF25: =N30 * (1 - AA25) -> 7.0281347 | AH25: =O30 * (1 - AC25) -> 10.832806 | AM25: Year 14 | AN25: =MIN(AF20,J23) * G23 * 20 -> 2.1559826e+08 | AO25: =MIN(AH20,J23) * G23 * 20 -> 2.4964009e+08 | AP25: =$N$10 + R25 * 20 -> 92908737 | AQ25: =$O$10 + U25 * 20 -> 1.5904469e+08 | AT25: =AF20 -> 6.3438678 | AU25: =AH20 -> 7.3455311 | AV25: =AN25-AP25 -> 1.2268952e+08 | AW25: =AO25-AQ25 -> 90595402
B26: Year 17 | C26: =IF(RAND() < (10-5)/(14-5), 5 + SQRT(RAND() * (10-5) * (14-5)), 14 - SQRT((1-RAND()) * (14-10) * (14-5))) -> 7.8419752 | F26: Year 17 | G26: =_xlfn.NORM.INV(RAND(),1900000,250000) -> 1808349.9 | I26: Year 17 | J26: =J25 * _xlfn.NORM.INV(RAND(),$J$7,$K$7) -> 207.71051 | M26: Year 15 | N26: =C24*$N$7 -> 10.825104 | O26: =C24*$O$7 -> 12.534331 | Q26: Year 15 | R26: =_xlfn.LOGNORM.INV(RAND(),$R$7,$R$8) -> 1382228.3 | T26: Year 15 | U26: =_xlfn.LOGNORM.INV(RAND(),$U$7,$U$8) -> 2454101.9 | Z26: Year 20 | AA26: =IF(X25=1, -LN(RAND()) / 5, 0) -> 0.02276309 | AC26: =IF(X25=1, -LN(RAND()) / 10, 0) -> 0.21537459 | AE26: Year 20 | AF26: =N31 * (1 - AA26) -> 11.566949 | AH26: =O31 * (1 - AC26) -> 10.753514 | AM26: Year 15 | AN26: =MIN(AF21,J24) * G24 * 20 -> 3.5947733e+08 | AO26: =MIN(AH21,J24) * G24 * 20 -> 4.1623691e+08 | AP26: =$N$10 + R26 * 20 -> 97644567 | AQ26: =$O$10 + U26 * 20 -> 1.5908204e+08 | AT26: =AF21 -> 10.825104 | AU26: =AH21 -> 12.534331 | AV26: =AN26-AP26 -> 2.6183277e+08 | AW26: =AO26-AQ26 -> 2.5715488e+08
B27: Year 18 | C27: =IF(RAND() < (10-5)/(14-5), 5 + SQRT(RAND() * (10-5) * (14-5)), 14 - SQRT((1-RAND()) * (14-10) * (14-5))) -> 10.473749 | F27: Year 18 | G27: =_xlfn.NORM.INV(RAND(),1900000,250000) -> 2041928.6 | I27: Year 18 | J27: =J26 * _xlfn.NORM.INV(RAND(),$J$7,$K$7) -> 208.2363 | M27: Year 16 | N27: =C25*$N$7 -> 7.4736064 | O27: =C25*$O$7 -> 8.6536496 | Q27: Year 16 | R27: =_xlfn.LOGNORM.INV(RAND(),$R$7,$R$8) -> 1738544.6 | T27: Year 16 | U27: =_xlfn.LOGNORM.INV(RAND(),$U$7,$U$8) -> 2412621.3 | AM27: Year 16 | AN27: =MIN(AF22,J25) * G25 * 20 -> 2.7129305e+08 | AO27: =MIN(AH22,J25) * G25 * 20 -> 3.1412879e+08 | AP27: =$N$10 + R27 * 20 -> 1.0477089e+08 | AQ27: =$O$10 + U27 * 20 -> 1.5825243e+08 | AT27: =AF22 -> 7.4736064 | AU27: =AH22 -> 8.6536496 | AV27: =AN27-AP27 -> 1.6652215e+08 | AW27: =AO27-AQ27 -> 1.5587636e+08
B28: Year 19 | C28: =IF(RAND() < (10-5)/(14-5), 5 + SQRT(RAND() * (10-5) * (14-5)), 14 - SQRT((1-RAND()) * (14-10) * (14-5))) -> 10.106789 | F28: Year 19 | G28: =_xlfn.NORM.INV(RAND(),1900000,250000) -> 1577094.5 | I28: Year 19 | J28: =J27 * _xlfn.NORM.INV(RAND(),$J$7,$K$7) -> 199.60567 | M28: Year 17 | N28: =C26*$N$7 -> 7.4498765 | O28: =C26*$O$7 -> 8.6261728 | Q28: Year 17 | R28: =_xlfn.LOGNORM.INV(RAND(),$R$7,$R$8) -> 1908062.9 | T28: Year 17 | U28: =_xlfn.LOGNORM.INV(RAND(),$U$7,$U$8) -> 2361869.4 | AM28: Year 17 | AN28: =MIN(AF23,J26) * G26 * 20 -> 1.6387479e+08 | AO28: =MIN(AH23,J26) * G26 * 20 -> 2.9781258e+08 | AP28: =$N$10 + R28 * 20 -> 1.0816126e+08 | AQ28: =$O$10 + U28 * 20 -> 1.5723739e+08 | AT28: =AF23 -> 4.5310586 | AU28: =AH23 -> 8.2343736 | AV28: =AN28-AP28 -> 55713529 | AW28: =AO28-AQ28 -> 1.4057519e+08
B29: Year 20 | C29: =IF(RAND() < (10-5)/(14-5), 5 + SQRT(RAND() * (10-5) * (14-5)), 14 - SQRT((1-RAND()) * (14-10) * (14-5))) -> 12.459349 | F29: Year 20 | G29: =_xlfn.NORM.INV(RAND(),1900000,250000) -> 1941054.7 | I29: Year 20 | J29: =J28 * _xlfn.NORM.INV(RAND(),$J$7,$K$7) -> 203.11941 | M29: Year 18 | N29: =C27*$N$7 -> 9.9500616 | O29: =C27*$O$7 -> 11.521124 | Q29: Year 18 | R29: =_xlfn.LOGNORM.INV(RAND(),$R$7,$R$8) -> 1622966.9 | T29: Year 18 | U29: =_xlfn.LOGNORM.INV(RAND(),$U$7,$U$8) -> 2193785.9 | AM29: Year 18 | AN29: =MIN(AF24,J27) * G27 * 20 -> 4.0634632e+08 | AO29: =MIN(AH24,J27) * G27 * 20 -> 4.7050626e+08 | AP29: =$N$10 + R29 * 20 -> 1.0245934e+08 | AQ29: =$O$10 + U29 * 20 -> 1.5387572e+08 | AT29: =AF24 -> 9.9500616 | AU29: =AH24 -> 11.521124 | AV29: =AN29-AP29 -> 3.0388698e+08 | AW29: =AO29-AQ29 -> 3.1663054e+08
M30: Year 19 | N30: =C28*$N$7 -> 9.6014491 | O30: =C28*$O$7 -> 11.117467 | Q30: Year 19 | R30: =_xlfn.LOGNORM.INV(RAND(),$R$7,$R$8) -> 1568781.9 | T30: Year 19 | U30: =_xlfn.LOGNORM.INV(RAND(),$U$7,$U$8) -> 2454301.5 | AM30: Year 19 | AN30: =MIN(AF25,J28) * G28 * 20 -> 2.2168065e+08 | AO30: =MIN(AH25,J28) * G28 * 20 -> 3.4168715e+08 | AP30: =$N$10 + R30 * 20 -> 1.0137564e+08 | AQ30: =$O$10 + U30 * 20 -> 1.5908603e+08 | AT30: =AF25 -> 7.0281347 | AU30: =AH25 -> 10.832806 | AV30: =AN30-AP30 -> 1.2030501e+08 | AW30: =AO30-AQ30 -> 1.8260112e+08
M31: Year 20 | N31: =C29*$N$7 -> 11.836381 | O31: =C29*$O$7 -> 13.705284 | Q31: Year 20 | R31: =_xlfn.LOGNORM.INV(RAND(),$R$7,$R$8) -> 1949127.4 | T31: Year 20 | U31: =_xlfn.LOGNORM.INV(RAND(),$U$7,$U$8) -> 2878820.2 | AM31: Year 20 | AN31: =MIN(AF26,J29) * G29 * 20 -> 4.490416e+08 | AO31: =MIN(AH26,J29) * G29 * 20 -> 4.1746317e+08 | AP31: =$N$10 + R31 * 20 -> 1.0898255e+08 | AQ31: =$O$10 + U31 * 20 -> 1.675764e+08 | AT31: =AF26 -> 11.566949 | AU31: =AH26 -> 10.753514 | AV31: =AN31-AP31 -> 3.4005905e+08 | AW31: =AO31-AQ31 -> 2.4988676e+08

Sheet Varity C - Syrah
C2: Varity C - Syrah | M2: Farming tecniques: | P2: Material costs per hectar | V2: Disese occurance | Y2: Exponential distribution | AE2: Adjusting yield to deases risk
M3: Traditional farming | N3: Modern farming | P3: Traditinal farming | S3: Modern farming | V3: 5 % probability of occuring each year | Y3: Traditonal | AB3: Modern | AE3: Traditional | AG3: Modern | AL3: Annual revenue | AN3: Costs | AP3: Disease events | AR3: Yield | AT3: Profit per year
C4: Annual yield | D4: Triangular distribution | F4: Price per ton | G4: Normal distribution | I4: Annual demand | J4: Normal distribution | L4: Annual fixed cost per hectar | M4: 3500000 | N4: 5500000 | P4: Mean | Q4: CLP 1 900 000,00 | S4: Mean | T4: 3000000 | V4: 0 if it dosent occure, 1 if it does | Y4: Lambda | Z4: 5 | AB4: 10
L5: Effect on the annual yield in percentage | M5: 0.95 | N5: 1.1 | P5: STD | Q5: CLP 250 000,00 | S5: STD | T5: 220000 | Y5: Average | Z5: 0.1 | AB5: 0.2
C6: Min | D6: 4 | F6: Mean | G6: 2500000 | I6: Mean | J6: 1.03 | L6: Total hectar per year | M6: 20 | N6: 20
C7: Mostly | D7: 8 | F7: STD | G7: 175000 | I7: STD | J7: 0.03 | P7: Scaled mean | Q7: 14.45 | S7: Scaled mean | T7: 14.86
C8: Max | D8: 12 | I8: Inn ton | L8: Fixed cost per year | M8: =M4*M6 -> 70000000 | N8: =N4*N6 -> 110000000 | P8: Scaled STD | Q8: 0.131 | S8: Scaled STD | T8: 0.073
M9: Adjusted yield traditional | N9: Adjusted yield modern | AL9: Traditional | AM9: Modern | AN9: Traditonal | AO9: Modern | AP9: Traditional | AQ9: Modern | AR9: Traditional | AS9: Modern | AT9: Traditonal | AU9: Modern
C10: Year 1 | D10: =IF(RAND() < (8-4)/(12-4), 4 + SQRT(RAND() * (8-4) * (12-4)), 12 - SQRT((1-RAND()) * (12-8) * (12-4))) -> 6.7325968 | F10: Year 1 | G10: =_xlfn.NORM.INV(RAND(),2500000,175000) -> 2527907.8 | I10: Year 1 | J10: 130 | L10: Year 1 | M10: =D10*$M$5 -> 6.395967 | N10: =D10 * $N$5 -> 7.4058565 | P10: Year 1 | Q10: =_xlfn.LOGNORM.INV(RAND(),$Q$7,$Q$8) -> 1993939.8 | S10: Year 1 | T10: =_xlfn.LOGNORM.INV(RAND(),$T$7,$T$8) -> 2762103.7 | V10: Year 1 | W10: =IF(RAND() < 0.05, 1, 0) -> 0 | Y10: Year 1 | Z10: =IF(W10=1, -LN(RAND()) / 5, 0) -> 0 | AB10: =IF(W10=1, -LN(RAND()) / 10, 0) -> 0 | AD10: Year 1 | AE10: =M10 * (1 - Z10) -> 6.395967 | AG10: =N10 * (1 - AB10) -> 7.4058565 | AK10: Year 1 | AL10: =MIN(AE10,J10) * G10 * 20 -> 3.2336829e+08 | AM10: =MIN(AG10,J10) * G10 * 20 -> 3.7442644e+08 | AN10: =$M$8 + Q10 * 20 -> 1.098788e+08 | AO10: =$N$8 + T10 * 20 -> 1.6524207e+08 | AP10: =SUM(W10:W29) -> 0 | AQ10: =SUM(W10:W29) -> 0 | AR10: =AE10 -> 6.395967 | AS10: =AG10 -> 7.4058565 | AT10: =AL10-AN10 -> 2.134895e+08 | AU10: =AM10-AO10 -> 2.0918437e+08
C11: Year 2 | D11: =IF(RAND() < (8-4)/(12-4), 4 + SQRT(RAND() * (8-4) * (12-4)), 12 - SQRT((1-RAND()) * (12-8) * (12-4))) -> 9.2516071 | F11: Year 2 | G11: =_xlfn.NORM.INV(RAND(),2500000,175000) -> 2740966.2 | I11: Year 2 | J11: =J10 * _xlfn.NORM.INV(RAND(),$J$6,$J$7) -> 131.09797 | L11: Year 2 | M11: =D11*$M$5 -> 8.7890268 | N11: =D11 * $N$5 -> 10.176768 | P11: Year 2 | Q11: =_xlfn.LOGNORM.INV(RAND(),$Q$7,$Q$8) -> 2083451.4 | S11: Year 2 | T11: =_xlfn.LOGNORM.INV(RAND(),$T$7,$T$8) -> 2947383.2 | V11: Year 2 | W11: =IF(RAND() < 0.05, 1, 0) -> 0 | Y11: Year 2 | Z11: =IF(W11=1, -LN(RAND()) / 5, 0) -> 0 | AB11: =IF(W11=1, -LN(RAND()) / 10, 0) -> 0 | AD11: Year 2 | AE11: =M11 * (1 - Z11) -> 8.7890268 | AG11: =N11 * (1 - AB11) -> 10.176768 | AK11: Year 2 | AL11: =MIN(AE11,J11) * G11 * 20 -> 4.8180851e+08 | AM11: =MIN(AG11,J11) * G11 * 20 -> 5.5788354e+08 | AN11: =$M$8 + Q11 * 20 -> 1.1166903e+08 | AO11: =$N$8 + T11 * 20 -> 1.6894766e+08 | AR11: =AE11 -> 8.7890268 | AS11: =AG11 -> 10.176768 | AT11: =AL11-AN11 -> 3.7013948e+08 | AU11: =AM11-AO11 -> 3.8893587e+08
C12: Year 3 | D12: =IF(RAND() < (8-4)/(12-4), 4 + SQRT(RAND() * (8-4) * (12-4)), 12 - SQRT((1-RAND()) * (12-8) * (12-4))) -> 4.9212431 | F12: Year 3 | G12: =_xlfn.NORM.INV(RAND(),2500000,175000) -> 2883654.8 | I12: Year 3 | J12: =J11 * _xlfn.NORM.INV(RAND(),$J$6,$J$7) -> 137.92243 | L12: Year 3 | M12: =D12*$M$5 -> 4.675181 | N12: =D12 * $N$5 -> 5.4133674 | P12: Year 3 | Q12: =_xlfn.LOGNORM.INV(RAND(),$Q$7,$Q$8) -> 2315672 | S12: Year 3 | T12: =_xlfn.LOGNORM.INV(RAND(),$T$7,$T$8) -> 2772103.9 | V12: Year 3 | W12: =IF(RAND() < 0.05, 1, 0) -> 0 | Y12: Year 3 | Z12: =IF(W12=1, -LN(RAND()) / 5, 0) -> 0 | AB12: =IF(W12=1, -LN(RAND()) / 10, 0) -> 0 | AD12: Year 3 | AE12: =M12 * (1 - Z12) -> 4.675181 | AG12: =N12 * (1 - AB12) -> 5.4133674 | AK12: Year 3 | AL12: =MIN(AE12,J12) * G12 * 20 -> 2.6963216e+08 | AM12: =MIN(AG12,J12) * G12 * 20 -> 3.1220565e+08 | AN12: =$M$8 + Q12 * 20 -> 1.1631344e+08 | AO12: =$N$8 + T12 * 20 -> 1.6544208e+08 | AR12: =AE12 -> 4.675181 | AS12: =AG12 -> 5.4133674 | AT12: =AL12-AN12 -> 1.5331872e+08 | AU12: =AM12-AO12 -> 1.4676358e+08
C13: Year 4 | D13: =IF(RAND() < (8-4)/(12-4), 4 + SQRT(RAND() * (8-4) * (12-4)), 12 - SQRT((1-RAND()) * (12-8) * (12-4))) -> 7.787607 | F13: Year 4 | G13: =_xlfn.NORM.INV(RAND(),2500000,175000) -> 2474088.8 | I13: Year 4 | J13: =J12 * _xlfn.NORM.INV(RAND(),$J$6,$J$7) -> 140.32707 | L13: Year 4 | M13: =D13*$M$5 -> 7.3982266 | N13: =D13 * $N$5 -> 8.5663677 | P13: Year 4 | Q13: =_xlfn.LOGNORM.INV(RAND(),$Q$7,$Q$8) -> 2009570.1 | S13: Year 4 | T13: =_xlfn.LOGNORM.INV(RAND(),$T$7,$T$8) -> 2548743.3 | V13: Year 4 | W13: =IF(RAND() < 0.05, 1, 0) -> 0 | Y13: Year 4 | Z13: =IF(W13=1, -LN(RAND()) / 5, 0) -> 0 | AB13: =IF(W13=1, -LN(RAND()) / 10, 0) -> 0 | AD13: Year 4 | AE13: =M13 * (1 - Z13) -> 7.3982266 | AG13: =N13 * (1 - AB13) -> 8.5663677 | AK13: Year 4 | AL13: =MIN(AE13,J13) * G13 * 20 -> 3.660774e+08 | AM13: =MIN(AG13,J13) * G13 * 20 -> 4.2387909e+08 | AN13: =$M$8 + Q13 * 20 -> 1.101914e+08 | AO13: =$N$8 + T13 * 20 -> 1.6097487e+08 | AR13: =AE13 -> 7.3982266 | AS13: =AG13 -> 8.5663677 | AT13: =AL13-AN13 -> 2.5588599e+08 | AU13: =AM13-AO13 -> 2.6290423e+08
C14: Year 5 | D14: =IF(RAND() < (8-4)/(12-4), 4 + SQRT(RAND() * (8-4) * (12-4)), 12 - SQRT((1-RAND()) * (12-8) * (12-4))) -> 11.168325 | F14: Year 5 | G14: =_xlfn.NORM.INV(RAND(),2500000,175000) -> 2683569.6 | I14: Year 5 | J14: =J13 * _xlfn.NORM.INV(RAND(),$J$6,$J$7) -> 142.90596 | L14: Year 5 | M14: =D14*$M$5 -> 10.609908 | N14: =D14 * $N$5 -> 12.285157 | P14: Year 5 | Q14: =_xlfn.LOGNORM.INV(RAND(),$Q$7,$Q$8) -> 1713561.9 | S14: Year 5 | T14: =_xlfn.LOGNORM.INV(RAND(),$T$7,$T$8) -> 3068062.7 | V14: Year 5 | W14: =IF(RAND() < 0.05, 1, 0) -> 0 | Y14: Year 5 | Z14: =IF(W14=1, -LN(RAND()) / 5, 0) -> 0 | AB14: =IF(W14=1, -LN(RAND()) / 10, 0) -> 0 | AD14: Year 5 | AE14: =M14 * (1 - Z14) -> 10.609908 | AG14: =N14 * (1 - AB14) -> 12.285157 | AK14: Year 5 | AL14: =MIN(AE14,J14) * G14 * 20 -> 5.6944855e+08 | AM14: =MIN(AG14,J14) * G14 * 20 -> 6.5936148e+08 | AN14: =$M$8 + Q14 * 20 -> 1.0427124e+08 | AO14: =$N$8 + T14 * 20 -> 1.7136125e+08 | AR14: =AE14 -> 10.609908 | AS14: =AG14 -> 12.285157 | AT14: =AL14-AN14 -> 4.6517732e+08 | AU14: =AM14-AO14 -> 4.8800023e+08
C15: Year 6 | D15: =IF(RAND() < (8-4)/(12-4), 4 + SQRT(RAND() * (8-4) * (12-4)), 12 - SQRT((1-RAND()) * (12-8) * (12-4))) -> 9.2852397 | F15: Year 6 | G15: =_xlfn.NORM.INV(RAND(),2500000,175000) -> 2324884.8 | I15: Year 6 | J15: =J14 * _xlfn.NORM.INV(RAND(),$J$6,$J$7) -> 146.19579 | L15: Year 6 | M15: =D15*$M$5 -> 8.8209777 | N15: =D15 * $N$5 -> 10.213764 | P15: Year 6 | Q15: =_xlfn.LOGNORM.INV(RAND(),$Q$7,$Q$8) -> 1835594.2 | S15: Year 6 | T15: =_xlfn.LOGNORM.INV(RAND(),$T$7,$T$8) -> 2933705.2 | V15: Year 6 | W15: =IF(RAND() < 0.05, 1, 0) -> 0 | Y15: Year 6 | Z15: =IF(W15=1, -LN(RAND()) / 5, 0) -> 0 | AB15: =IF(W15=1, -LN(RAND()) / 10, 0) -> 0 | AD15: Year 6 | AE15: =M15 * (1 - Z15) -> 8.8209777 | AG15: =N15 * (1 - AB15) -> 10.213764 | AK15: Year 6 | AL15: =MIN(AE15,J15) * G15 * 20 -> 4.1015515e+08 | AM15: =MIN(AG15,J15) * G15 * 20 -> 4.7491649e+08 | AN15: =$M$8 + Q15 * 20 -> 1.0671188e+08 | AO15: =$N$8 + T15 * 20 -> 1.686741e+08 | AR15: =AE15 -> 8.8209777 | AS15: =AG15 -> 10.213764 | AT15: =AL15-AN15 -> 3.0344326e+08 | AU15: =AM15-AO15 -> 3.0624238e+08
C16: Year 7 | D16: =IF(RAND() < (8-4)/(12-4), 4 + SQRT(RAND() * (8-4) * (12-4)), 12 - SQRT((1-RAND()) * (12-8) * (12-4))) -> 5.978401 | F16: Year 7 | G16: =_xlfn.NORM.INV(RAND(),2500000,175000) -> 2481870.6 | I16: Year 7 | J16: =J15 * _xlfn.NORM.INV(RAND(),$J$6,$J$7) -> 155.85328 | L16: Year 7 | M16: =D16*$M$5 -> 5.679481 | N16: =D16 * $N$5 -> 6.5762412 | P16: Year 7 | Q16: =_xlfn.LOGNORM.INV(RAND(),$Q$7,$Q$8) -> 2115808.4 | S16: Year 7 | T16: =_xlfn.LOGNORM.INV(RAND(),$T$7,$T$8) -> 2871340.6 | V16: Year 7 | W16: =IF(RAND() < 0.05, 1, 0) -> 0 | Y16: Year 7 | Z16: =IF(W16=1, -LN(RAND()) / 5, 0) -> 0 | AB16: =IF(W16=1, -LN(RAND()) / 10, 0) -> 0 | AD16: Year 7 | AE16: =M16 * (1 - Z16) -> 5.679481 | AG16: =N16 * (1 - AB16) -> 6.5762412 | AK16: Year 7 | AL16: =MIN(AE16,J16) * G16 * 20 -> 2.8191474e+08 | AM16: =MIN(AG16,J16) * G16 * 20 -> 3.2642759e+08 | AN16: =$M$8 + Q16 * 20 -> 1.1231617e+08 | AO16: =$N$8 + T16 * 20 -> 1.6742681e+08 | AR16: =AE16 -> 5.679481 | AS16: =AG16 -> 6.5762412 | AT16: =AL16-AN16 -> 1.6959857e+08 | AU16: =AM16-AO16 -> 1.5900078e+08
C17: Year 8 | D17: =IF(RAND() < (8-4)/(12-4), 4 + SQRT(RAND() * (8-4) * (12-4)), 12 - SQRT((1-RAND()) * (12-8) * (12-4))) -> 9.2968132 | F17: Year 8 | G17: =_xlfn.NORM.INV(RAND(),2500000,175000) -> 2530025.8 | I17: Year 8 | J17: =J16 * _xlfn.NORM.INV(RAND(),$J$6,$J$7) -> 154.14298 | L17: Year 8 | M17: =D17*$M$5 -> 8.8319726 | N17: =D17 * $N$5 -> 10.226495 | P17: Year 8 | Q17: =_xlfn.LOGNORM.INV(RAND(),$Q$7,$Q$8) -> 1591958.2 | S17: Year 8 | T17: =_xlfn.LOGNORM.INV(RAND(),$T$7,$T$8) -> 2932476.6 | V17: Year 8 | W17: =IF(RAND() < 0.05, 1, 0) -> 0 | Y17: Year 8 | Z17: =IF(W17=1, -LN(RAND()) / 5, 0) -> 0 | AB17: =IF(W17=1, -LN(RAND()) / 10, 0) -> 0 | AD17: Year 8 | AE17: =M17 * (1 - Z17) -> 8.8319726 | AG17: =N17 * (1 - AB17) -> 10.226495 | AK17: Year 8 | AL17: =MIN(AE17,J17) * G17 * 20 -> 4.4690237e+08 | AM17: =MIN(AG17,J17) * G17 * 20 -> 5.174659e+08 | AN17: =$M$8 + Q17 * 20 -> 1.0183916e+08 | AO17: =$N$8 + T17 * 20 -> 1.6864953e+08 | AR17: =AE17 -> 8.8319726 | AS17: =AG17 -> 10.226495 | AT17: =AL17-AN17 -> 3.450632e+08 | AU17: =AM17-AO17 -> 3.4881637e+08
C18: Year 9 | D18: =IF(RAND() < (8-4)/(12-4), 4 + SQRT(RAND() * (8-4) * (12-4)), 12 - SQRT((1-RAND()) * (12-8) * (12-4))) -> 5.1190926 | F18: Year 9 | G18: =_xlfn.NORM.INV(RAND(),2500000,175000) -> 2250844.2 | I18: Year 9 | J18: =J17 * _xlfn.NORM.INV(RAND(),$J$6,$J$7) -> 160.82551 | L18: Year 9 | M18: =D18*$M$5 -> 4.863138 | N18: =D18 * $N$5 -> 5.6310019 | P18: Year 9 | Q18: =_xlfn.LOGNORM.INV(RAND(),$Q$7,$Q$8) -> 1836179.2 | S18: Year 9 | T18: =_xlfn.LOGNORM.INV(RAND(),$T$7,$T$8) -> 2662711.2 | V18: Year 9 | W18: =IF(RAND() < 0.05, 1, 0) -> 0 | Y18: Year 9 | Z18: =IF(W18=1, -LN(RAND()) / 5, 0) -> 0 | AB18: =IF(W18=1, -LN(RAND()) / 10, 0) -> 0 | AD18: Year 9 | AE18: =M18 * (1 - Z18) -> 4.863138 | AG18: =N18 * (1 - AB18) -> 5.6310019 | AK18: Year 9 | AL18: =MIN(AE18,J18) * G18 * 20 -> 2.1892331e+08 | AM18: =MIN(AG18,J18) * G18 * 20 -> 2.5349015e+08 | AN18: =$M$8 + Q18 * 20 -> 1.0672358e+08 | AO18: =$N$8 + T18 * 20 -> 1.6325422e+08 | AR18: =AE18 -> 4.863138 | AS18: =AG18 -> 5.6310019 | AT18: =AL18-AN18 -> 1.1219973e+08 | AU18: =AM18-AO18 -> 90235929
C19: Year 10 | D19: =IF(RAND() < (8-4)/(12-4), 4 + SQRT(RAND() * (8-4) * (12-4)), 12 - SQRT((1-RAND()) * (12-8) * (12-4))) -> 7.3880108 | F19: Year 10 | G19: =_xlfn.NORM.INV(RAND(),2500000,175000) -> 2529418.3 | I19: Year 10 | J19: =J18 * _xlfn.NORM.INV(RAND(),$J$6,$J$7) -> 170.34201 | L19: Year 10 | M19: =D19*$M$5 -> 7.0186102 | N19: =D19 * $N$5 -> 8.1268119 | P19: Year 10 | Q19: =_xlfn.LOGNORM.INV(RAND(),$Q$7,$Q$8) -> 1765403.7 | S19: Year 10 | T19: =_xlfn.LOGNORM.INV(RAND(),$T$7,$T$8) -> 2553323.5 | V19: Year 10 | W19: =IF(RAND() < 0.05, 1, 0) -> 0 | Y19: Year 10 | Z19: =IF(W19=1, -LN(RAND()) / 5, 0) -> 0 | AB19: =IF(W19=1, -LN(RAND()) / 10, 0) -> 0 | AD19: Year 10 | AE19: =M19 * (1 - Z19) -> 7.0186102 | AG19: =N19 * (1 - AB19) -> 8.1268119 | AK19: Year 10 | AL19: =MIN(AE19,J19) * G19 * 20 -> 3.5506003e+08 | AM19: =MIN(AG19,J19) * G19 * 20 -> 4.1112214e+08 | AN19: =$M$8 + Q19 * 20 -> 1.0530807e+08 | AO19: =$N$8 + T19 * 20 -> 1.6106647e+08 | AR19: =AE19 -> 7.0186102 | AS19: =AG19 -> 8.1268119 | AT19: =AL19-AN19 -> 2.4975195e+08 | AU19: =AM19-AO19 -> 2.5005567e+08
